<robot name = "robot">
    <link name="Link0">
        <inertial>
            <origin xyz="0 0 0.28862579059622695" rpy="0 0 0"/>
            <mass value="1" />
            <inertia ixx="100" ixy="0" ixz="0" iyy="100" iyz="0" izz="100" />
        </inertial>
        <visual>
            <origin xyz="0 0 0.28862579059622695" rpy="0 0 0"/>
            <geometry>
                <box size="0.49222885497054225 0.5725636893709081 0.5772515811924539" />
            </geometry>
            <material name="Green">
                <color rgba="0 1.0 0 1.0"/>
            </material>
        </visual>
        <collision>
            <origin xyz="0 0 0.28862579059622695" rpy="0 0 0"/>
            <geometry>
                <box size="0.49222885497054225 0.5725636893709081 0.5772515811924539" />
            </geometry>
        </collision>
    </link>
    <joint name="Link0_Link1" type="revolute">
       <parent link="Link0"/>
       <child  link="Link1"/>
       <origin rpy="0 0 0" xyz="0 0 0.5772515811924539" />
       <axis xyz="0 1 0"/>
       <limit effort="0.0" lower="-3.14159" upper="3.14159" velocity="0.0"/>
    </joint>
    <link name="Link1">
        <inertial>
            <origin xyz="0 0 0.34899673637863615" rpy="0 0 0"/>
            <mass value="1" />
            <inertia ixx="100" ixy="0" ixz="0" iyy="100" iyz="0" izz="100" />
        </inertial>
        <visual>
            <origin xyz="0 0 0.34899673637863615" rpy="0 0 0"/>
            <geometry>
                <box size="0.26917906905728106 0.3971983633409346 0.6979934727572723" />
            </geometry>
            <material name="Blue">
                <color rgba="0 0 1.0 1.0"/>
            </material>
        </visual>
        <collision>
            <origin xyz="0 0 0.34899673637863615" rpy="0 0 0"/>
            <geometry>
                <box size="0.26917906905728106 0.3971983633409346 0.6979934727572723" />
            </geometry>
        </collision>
    </link>
    <joint name="Link0_Link2" type="revolute">
       <parent link="Link0"/>
       <child  link="Link2"/>
       <origin rpy="0 0 0" xyz="0 0 0.5772515811924539" />
       <axis xyz="0 1 0"/>
       <limit effort="0.0" lower="-3.14159" upper="3.14159" velocity="0.0"/>
    </joint>
    <link name="Link2">
        <inertial>
            <origin xyz="0 0 0.2760061150678247" rpy="0 0 0"/>
            <mass value="1" />
            <inertia ixx="100" ixy="0" ixz="0" iyy="100" iyz="0" izz="100" />
        </inertial>
        <visual>
            <origin xyz="0 0 0.2760061150678247" rpy="0 0 0"/>
            <geometry>
                <box size="0.632459074375797 0.7919461307819684 0.5520122301356494" />
            </geometry>
            <material name="Blue">
                <color rgba="0 0 1.0 1.0"/>
            </material>
        </visual>
        <collision>
            <origin xyz="0 0 0.2760061150678247" rpy="0 0 0"/>
            <geometry>
                <box size="0.632459074375797 0.7919461307819684 0.5520122301356494" />
            </geometry>
        </collision>
    </link>
    <joint name="Link2_Link3" type="revolute">
       <parent link="Link2"/>
       <child  link="Link3"/>
       <origin rpy="0 0 0" xyz="0 -0.3959730653909842 0.2760061150678247" />
       <axis xyz="0 1 0"/>
       <limit effort="0.0" lower="-3.14159" upper="3.14159" velocity="0.0"/>
    </joint>
    <link name="Link3">
        <inertial>
            <origin xyz="0 -0.38434933448246944 0" rpy="0 0 0"/>
            <mass value="1" />
            <inertia ixx="100" ixy="0" ixz="0" iyy="100" iyz="0" izz="100" />
        </inertial>
        <visual>
            <origin xyz="0 -0.38434933448246944 0" rpy="0 0 0"/>
            <geometry>
                <box size="0.5363076517631122 0.7686986689649389 0.22531307360626648" />
            </geometry>
            <material name="Blue">
                <color rgba="0 0 1.0 1.0"/>
            </material>
        </visual>
        <collision>
            <origin xyz="0 -0.38434933448246944 0" rpy="0 0 0"/>
            <geometry>
                <box size="0.5363076517631122 0.7686986689649389 0.22531307360626648" />
            </geometry>
        </collision>
    </link>
    <joint name="Link1_Link4" type="revolute">
       <parent link="Link1"/>
       <child  link="Link4"/>
       <origin rpy="0 0 0" xyz="0 -0.1985991816704673 0.34899673637863615" />
       <axis xyz="0 0 1"/>
       <limit effort="0.0" lower="-3.14159" upper="3.14159" velocity="0.0"/>
    </joint>
    <link name="Link4">
        <inertial>
            <origin xyz="0 -0.24732424117358223 0" rpy="0 0 0"/>
            <mass value="1" />
            <inertia ixx="100" ixy="0" ixz="0" iyy="100" iyz="0" izz="100" />
        </inertial>
        <visual>
            <origin xyz="0 -0.24732424117358223 0" rpy="0 0 0"/>
            <geometry>
                <box size="0.31454991730079823 0.49464848234716446 0.28121889528573096" />
            </geometry>
            <material name="Blue">
                <color rgba="0 0 1.0 1.0"/>
            </material>
        </visual>
        <collision>
            <origin xyz="0 -0.24732424117358223 0" rpy="0 0 0"/>
            <geometry>
                <box size="0.31454991730079823 0.49464848234716446 0.28121889528573096" />
            </geometry>
        </collision>
    </link>
</robot>