<robot name = "robot">
    <link name="Link0">
        <inertial>
            <origin xyz="0 0 0.15259989388864015" rpy="0 0 0"/>
            <mass value="1" />
            <inertia ixx="100" ixy="0" ixz="0" iyy="100" iyz="0" izz="100" />
        </inertial>
        <visual>
            <origin xyz="0 0 0.15259989388864015" rpy="0 0 0"/>
            <geometry>
                <box size="0.22304382885820379 0.7282804119154769 0.3051997877772803" />
            </geometry>
            <material name="Green">
                <color rgba="0 1.0 0 1.0"/>
            </material>
        </visual>
        <collision>
            <origin xyz="0 0 0.15259989388864015" rpy="0 0 0"/>
            <geometry>
                <box size="0.22304382885820379 0.7282804119154769 0.3051997877772803" />
            </geometry>
        </collision>
    </link>
    <joint name="Link0_Link1" type="revolute">
       <parent link="Link0"/>
       <child  link="Link1"/>
       <origin rpy="0 0 0" xyz="-0.11152191442910189 0 0.15259989388864015" />
       <axis xyz="0 1 0"/>
       <limit effort="0.0" lower="-3.14159" upper="3.14159" velocity="0.0"/>
    </joint>
    <link name="Link1">
        <inertial>
            <origin xyz="-0.2504933118980195 0 0" rpy="0 0 0"/>
            <mass value="1" />
            <inertia ixx="100" ixy="0" ixz="0" iyy="100" iyz="0" izz="100" />
        </inertial>
        <visual>
            <origin xyz="-0.2504933118980195 0 0" rpy="0 0 0"/>
            <geometry>
                <box size="0.500986623796039 0.7129407158692302 0.8590157648899042" />
            </geometry>
            <material name="Green">
                <color rgba="0 1.0 0 1.0"/>
            </material>
        </visual>
        <collision>
            <origin xyz="-0.2504933118980195 0 0" rpy="0 0 0"/>
            <geometry>
                <box size="0.500986623796039 0.7129407158692302 0.8590157648899042" />
            </geometry>
        </collision>
    </link>
    <joint name="Link0_Link2" type="revolute">
       <parent link="Link0"/>
       <child  link="Link2"/>
       <origin rpy="0 0 0" xyz="0 -0.36414020595773844 0.15259989388864015" />
       <axis xyz="1 0 0"/>
       <limit effort="0.0" lower="-3.14159" upper="3.14159" velocity="0.0"/>
    </joint>
    <link name="Link2">
        <inertial>
            <origin xyz="0 -0.22884689351892995 0" rpy="0 0 0"/>
            <mass value="1" />
            <inertia ixx="100" ixy="0" ixz="0" iyy="100" iyz="0" izz="100" />
        </inertial>
        <visual>
            <origin xyz="0 -0.22884689351892995 0" rpy="0 0 0"/>
            <geometry>
                <box size="0.6284578718160516 0.4576937870378599 0.7071067314223181" />
            </geometry>
            <material name="Green">
                <color rgba="0 1.0 0 1.0"/>
            </material>
        </visual>
        <collision>
            <origin xyz="0 -0.22884689351892995 0" rpy="0 0 0"/>
            <geometry>
                <box size="0.6284578718160516 0.4576937870378599 0.7071067314223181" />
            </geometry>
        </collision>
    </link>
</robot>