<robot name = "robot">
    <link name="Link0">
        <inertial>
            <origin xyz="0 0 0.306817488773093" rpy="0 0 0"/>
            <mass value="1" />
            <inertia ixx="100" ixy="0" ixz="0" iyy="100" iyz="0" izz="100" />
        </inertial>
        <visual>
            <origin xyz="0 0 0.306817488773093" rpy="0 0 0"/>
            <geometry>
                <box size="0.4978258309485384 0.4478033514201856 0.613634977546186" />
            </geometry>
            <material name="a">
                <color rgba="0.1 0.2 0.9 0.95"/>
            </material>
        </visual>
        <collision>
            <origin xyz="0 0 0.306817488773093" rpy="0 0 0"/>
            <geometry>
                <box size="0.4978258309485384 0.4478033514201856 0.613634977546186" />
            </geometry>
        </collision>
    </link>
    <joint name="Link0_Link1" type="revolute">
       <parent link="Link0"/>
       <child  link="Link1"/>
       <origin rpy="0 0 0" xyz="0 0 0.613634977546186" />
       <axis xyz="0 1 0"/>
       <limit effort="0.0" lower="-3.14159" upper="3.14159" velocity="0.0"/>
    </joint>
    <link name="Link1">
        <inertial>
            <origin xyz="0 0 0.11945424485034961" rpy="0 0 0"/>
            <mass value="1" />
            <inertia ixx="100" ixy="0" ixz="0" iyy="100" iyz="0" izz="100" />
        </inertial>
        <visual>
            <origin xyz="0 0 0.11945424485034961" rpy="0 0 0"/>
            <geometry>
                <box size="0.34205276265649176 0.9002867237729214 0.23890848970069922" />
            </geometry>
            <material name="a">
                <color rgba="0.4 0.7 0.9 0.95"/>
            </material>
        </visual>
        <collision>
            <origin xyz="0 0 0.11945424485034961" rpy="0 0 0"/>
            <geometry>
                <box size="0.34205276265649176 0.9002867237729214 0.23890848970069922" />
            </geometry>
        </collision>
    </link>
    <joint name="Link1_Link2" type="revolute">
       <parent link="Link1"/>
       <child  link="Link2"/>
       <origin rpy="0 0 0" xyz="0 -0.4501433618864607 0.11945424485034961" />
       <axis xyz="0 1 0"/>
       <limit effort="0.0" lower="-3.14159" upper="3.14159" velocity="0.0"/>
    </joint>
    <link name="Link2">
        <inertial>
            <origin xyz="0 -0.4809405379481708 0" rpy="0 0 0"/>
            <mass value="1" />
            <inertia ixx="100" ixy="0" ixz="0" iyy="100" iyz="0" izz="100" />
        </inertial>
        <visual>
            <origin xyz="0 -0.4809405379481708 0" rpy="0 0 0"/>
            <geometry>
                <box size="0.2444047551299749 0.9618810758963416 0.3122232660849121" />
            </geometry>
            <material name="b">
                <color rgba="0.6 0.6 0.8 0.95"/>
            </material>
        </visual>
        <collision>
            <origin xyz="0 -0.4809405379481708 0" rpy="0 0 0"/>
            <geometry>
                <box size="0.2444047551299749 0.9618810758963416 0.3122232660849121" />
            </geometry>
        </collision>
    </link>
    <joint name="Link2_Link3" type="revolute">
       <parent link="Link2"/>
       <child  link="Link3"/>
       <origin rpy="0 0 0" xyz="0 -0.4809405379481708 0.15611163304245604" />
       <axis xyz="1 0 0"/>
       <limit effort="0.0" lower="-3.14159" upper="3.14159" velocity="0.0"/>
    </joint>
    <link name="Link3">
        <inertial>
            <origin xyz="0 0 0.4300492037713374" rpy="0 0 0"/>
            <mass value="1" />
            <inertia ixx="100" ixy="0" ixz="0" iyy="100" iyz="0" izz="100" />
        </inertial>
        <visual>
            <origin xyz="0 0 0.4300492037713374" rpy="0 0 0"/>
            <geometry>
                <box size="0.5388356496295637 0.6728203608745853 0.8600984075426747" />
            </geometry>
            <material name="c">
                <color rgba="0.8 0.9 0.6 0.95"/>
            </material>
        </visual>
        <collision>
            <origin xyz="0 0 0.4300492037713374" rpy="0 0 0"/>
            <geometry>
                <box size="0.5388356496295637 0.6728203608745853 0.8600984075426747" />
            </geometry>
        </collision>
    </link>
    <joint name="Link3_Link4" type="revolute">
       <parent link="Link3"/>
       <child  link="Link4"/>
       <origin rpy="0 0 0" xyz="0 0 0.8600984075426747" />
       <axis xyz="0 0 1"/>
       <limit effort="0.0" lower="-3.14159" upper="3.14159" velocity="0.0"/>
    </joint>
    <link name="Link4">
        <inertial>
            <origin xyz="0 0 0.184581152126145" rpy="0 0 0"/>
            <mass value="1" />
            <inertia ixx="100" ixy="0" ixz="0" iyy="100" iyz="0" izz="100" />
        </inertial>
        <visual>
            <origin xyz="0 0 0.184581152126145" rpy="0 0 0"/>
            <geometry>
                <box size="0.335997403016605 0.9821542883784131 0.36916230425229" />
            </geometry>
            <material name="d">
                <color rgba="0.9 0.4 0.5 0.95"/>
            </material>
        </visual>
        <collision>
            <origin xyz="0 0 0.184581152126145" rpy="0 0 0"/>
            <geometry>
                <box size="0.335997403016605 0.9821542883784131 0.36916230425229" />
            </geometry>
        </collision>
    </link>
    <joint name="Link3_Link5" type="revolute">
       <parent link="Link3"/>
       <child  link="Link5"/>
       <origin rpy="0 0 0" xyz="-0.2694178248147818 0 0.4300492037713374" />
       <axis xyz="0 1 0"/>
       <limit effort="0.0" lower="-3.14159" upper="3.14159" velocity="0.0"/>
    </joint>
    <link name="Link5">
        <inertial>
            <origin xyz="-0.3063577274976819 0 0" rpy="0 0 0"/>
            <mass value="1" />
            <inertia ixx="100" ixy="0" ixz="0" iyy="100" iyz="0" izz="100" />
        </inertial>
        <visual>
            <origin xyz="-0.3063577274976819 0 0" rpy="0 0 0"/>
            <geometry>
                <box size="0.6127154549953638 0.9796288362063394 0.5283167591914335" />
            </geometry>
            <material name="e">
                <color rgba="0.5 0.2 0.9 0.95"/>
            </material>
        </visual>
        <collision>
            <origin xyz="-0.3063577274976819 0 0" rpy="0 0 0"/>
            <geometry>
                <box size="0.6127154549953638 0.9796288362063394 0.5283167591914335" />
            </geometry>
        </collision>
    </link>
    <joint name="Link2_Link6" type="revolute">
       <parent link="Link2"/>
       <child  link="Link6"/>
       <origin rpy="0 0 0" xyz="-0.12220237756498745 -0.4809405379481708 0" />
       <axis xyz="1 0 0"/>
       <limit effort="0.0" lower="-3.14159" upper="3.14159" velocity="0.0"/>
    </joint>
    <link name="Link6">
        <inertial>
            <origin xyz="-0.3971877783637183 0 0" rpy="0 0 0"/>
            <mass value="1" />
            <inertia ixx="100" ixy="0" ixz="0" iyy="100" iyz="0" izz="100" />
        </inertial>
        <visual>
            <origin xyz="-0.3971877783637183 0 0" rpy="0 0 0"/>
            <geometry>
                <box size="0.7943755567274366 0.921799517163796 0.3033584595793688" />
            </geometry>
            <material name="f">
                <color rgba="0.4 0.2 0.3 0.95"/>
            </material>
        </visual>
        <collision>
            <origin xyz="-0.3971877783637183 0 0" rpy="0 0 0"/>
            <geometry>
                <box size="0.7943755567274366 0.921799517163796 0.3033584595793688" />
            </geometry>
        </collision>
    </link>
</robot>