<robot name = "robot">
    <link name="Link0">
        <inertial>
            <origin xyz="0 0 0.192065905589079" rpy="0 0 0"/>
            <mass value="1" />
            <inertia ixx="100" ixy="0" ixz="0" iyy="100" iyz="0" izz="100" />
        </inertial>
        <visual>
            <origin xyz="0 0 0.192065905589079" rpy="0 0 0"/>
            <geometry>
                <box size="0.6028039009280342 0.446334971432933 0.384131811178158" />
            </geometry>
            <material name="Green">
                <color rgba="0 1.0 0 1.0"/>
            </material>
        </visual>
        <collision>
            <origin xyz="0 0 0.192065905589079" rpy="0 0 0"/>
            <geometry>
                <box size="0.6028039009280342 0.446334971432933 0.384131811178158" />
            </geometry>
        </collision>
    </link>
    <joint name="Link0_Link1" type="revolute">
       <parent link="Link0"/>
       <child  link="Link1"/>
       <origin rpy="0 0 0" xyz="0.3014019504640171 0 0.192065905589079" />
       <axis xyz="1 0 0"/>
       <limit effort="0.0" lower="-3.14159" upper="3.14159" velocity="0.0"/>
    </joint>
    <link name="Link1">
        <inertial>
            <origin xyz="0.13516618725974128 0 0" rpy="0 0 0"/>
            <mass value="1" />
            <inertia ixx="100" ixy="0" ixz="0" iyy="100" iyz="0" izz="100" />
        </inertial>
        <visual>
            <origin xyz="0.13516618725974128 0 0" rpy="0 0 0"/>
            <geometry>
                <box size="0.27033237451948255 0.8758065318572927 0.38963279439295606" />
            </geometry>
            <material name="Blue">
                <color rgba="0 0 1.0 1.0"/>
            </material>
        </visual>
        <collision>
            <origin xyz="0.13516618725974128 0 0" rpy="0 0 0"/>
            <geometry>
                <box size="0.27033237451948255 0.8758065318572927 0.38963279439295606" />
            </geometry>
        </collision>
    </link>
    <joint name="Link0_Link2" type="revolute">
       <parent link="Link0"/>
       <child  link="Link2"/>
       <origin rpy="0 0 0" xyz="-0.3014019504640171 0 0.192065905589079" />
       <axis xyz="1 0 0"/>
       <limit effort="0.0" lower="-3.14159" upper="3.14159" velocity="0.0"/>
    </joint>
    <link name="Link2">
        <inertial>
            <origin xyz="-0.36854165329825883 0 0" rpy="0 0 0"/>
            <mass value="1" />
            <inertia ixx="100" ixy="0" ixz="0" iyy="100" iyz="0" izz="100" />
        </inertial>
        <visual>
            <origin xyz="-0.36854165329825883 0 0" rpy="0 0 0"/>
            <geometry>
                <box size="0.7370833065965177 0.5075208673234999 0.24942180169718695" />
            </geometry>
            <material name="Green">
                <color rgba="0 1.0 0 1.0"/>
            </material>
        </visual>
        <collision>
            <origin xyz="-0.36854165329825883 0 0" rpy="0 0 0"/>
            <geometry>
                <box size="0.7370833065965177 0.5075208673234999 0.24942180169718695" />
            </geometry>
        </collision>
    </link>
    <joint name="Link1_Link3" type="revolute">
       <parent link="Link1"/>
       <child  link="Link3"/>
       <origin rpy="0 0 0" xyz="0.13516618725974128 -0.43790326592864637 0" />
       <axis xyz="0 1 0"/>
       <limit effort="0.0" lower="-3.14159" upper="3.14159" velocity="0.0"/>
    </joint>
    <link name="Link3">
        <inertial>
            <origin xyz="0 -0.12075612012608619 0" rpy="0 0 0"/>
            <mass value="1" />
            <inertia ixx="100" ixy="0" ixz="0" iyy="100" iyz="0" izz="100" />
        </inertial>
        <visual>
            <origin xyz="0 -0.12075612012608619 0" rpy="0 0 0"/>
            <geometry>
                <box size="0.7340574458651832 0.24151224025217238 0.45877031747853203" />
            </geometry>
            <material name="Green">
                <color rgba="0 1.0 0 1.0"/>
            </material>
        </visual>
        <collision>
            <origin xyz="0 -0.12075612012608619 0" rpy="0 0 0"/>
            <geometry>
                <box size="0.7340574458651832 0.24151224025217238 0.45877031747853203" />
            </geometry>
        </collision>
    </link>
</robot>