<robot name = "robot">
    <link name="Link0">
        <inertial>
            <origin xyz="0 0 0.3606078840528968" rpy="0 0 0"/>
            <mass value="1" />
            <inertia ixx="100" ixy="0" ixz="0" iyy="100" iyz="0" izz="100" />
        </inertial>
        <visual>
            <origin xyz="0 0 0.3606078840528968" rpy="0 0 0"/>
            <geometry>
                <box size="0.28761541259314777 0.34689391757525795 0.7212157681057936" />
            </geometry>
            <material name="Green">
                <color rgba="0 1.0 0 1.0"/>
            </material>
        </visual>
        <collision>
            <origin xyz="0 0 0.3606078840528968" rpy="0 0 0"/>
            <geometry>
                <box size="0.28761541259314777 0.34689391757525795 0.7212157681057936" />
            </geometry>
        </collision>
    </link>
    <joint name="Link0_Link1" type="revolute">
       <parent link="Link0"/>
       <child  link="Link1"/>
       <origin rpy="0 0 0" xyz="0 0 0.7212157681057936" />
       <axis xyz="0 0 1"/>
       <limit effort="0.0" lower="-3.14159" upper="3.14159" velocity="0.0"/>
    </joint>
    <link name="Link1">
        <inertial>
            <origin xyz="0 0 0.10262137618464524" rpy="0 0 0"/>
            <mass value="1" />
            <inertia ixx="100" ixy="0" ixz="0" iyy="100" iyz="0" izz="100" />
        </inertial>
        <visual>
            <origin xyz="0 0 0.10262137618464524" rpy="0 0 0"/>
            <geometry>
                <box size="0.9282163704206605 0.644510746496533 0.2052427523692905" />
            </geometry>
            <material name="Blue">
                <color rgba="0 0 1.0 1.0"/>
            </material>
        </visual>
        <collision>
            <origin xyz="0 0 0.10262137618464524" rpy="0 0 0"/>
            <geometry>
                <box size="0.9282163704206605 0.644510746496533 0.2052427523692905" />
            </geometry>
        </collision>
    </link>
    <joint name="Link0_Link2" type="revolute">
       <parent link="Link0"/>
       <child  link="Link2"/>
       <origin rpy="0 0 0" xyz="-0.14380770629657388 0 0.3606078840528968" />
       <axis xyz="0 0 1"/>
       <limit effort="0.0" lower="-3.14159" upper="3.14159" velocity="0.0"/>
    </joint>
    <link name="Link2">
        <inertial>
            <origin xyz="-0.2409728112907602 0 0" rpy="0 0 0"/>
            <mass value="1" />
            <inertia ixx="100" ixy="0" ixz="0" iyy="100" iyz="0" izz="100" />
        </inertial>
        <visual>
            <origin xyz="-0.2409728112907602 0 0" rpy="0 0 0"/>
            <geometry>
                <box size="0.4819456225815204 0.426275613587672 0.8101253005127822" />
            </geometry>
            <material name="Green">
                <color rgba="0 1.0 0 1.0"/>
            </material>
        </visual>
        <collision>
            <origin xyz="-0.2409728112907602 0 0" rpy="0 0 0"/>
            <geometry>
                <box size="0.4819456225815204 0.426275613587672 0.8101253005127822" />
            </geometry>
        </collision>
    </link>
    <joint name="Link2_Link3" type="revolute">
       <parent link="Link2"/>
       <child  link="Link3"/>
       <origin rpy="0 0 0" xyz="-0.2409728112907602 0.213137806793836 0" />
       <axis xyz="1 0 0"/>
       <limit effort="0.0" lower="-3.14159" upper="3.14159" velocity="0.0"/>
    </joint>
    <link name="Link3">
        <inertial>
            <origin xyz="0 0.2837904908537926 0" rpy="0 0 0"/>
            <mass value="1" />
            <inertia ixx="100" ixy="0" ixz="0" iyy="100" iyz="0" izz="100" />
        </inertial>
        <visual>
            <origin xyz="0 0.2837904908537926 0" rpy="0 0 0"/>
            <geometry>
                <box size="0.8252386890419501 0.5675809817075852 0.9358506333638077" />
            </geometry>
            <material name="Green">
                <color rgba="0 1.0 0 1.0"/>
            </material>
        </visual>
        <collision>
            <origin xyz="0 0.2837904908537926 0" rpy="0 0 0"/>
            <geometry>
                <box size="0.8252386890419501 0.5675809817075852 0.9358506333638077" />
            </geometry>
        </collision>
    </link>
</robot>