<robot name = "robot">
    <link name="Link0">
        <inertial>
            <origin xyz="0 0 0.11387920794735701" rpy="0 0 0"/>
            <mass value="1" />
            <inertia ixx="100" ixy="0" ixz="0" iyy="100" iyz="0" izz="100" />
        </inertial>
        <visual>
            <origin xyz="0 0 0.11387920794735701" rpy="0 0 0"/>
            <geometry>
                <box size="0.2263642155711163 0.8971948235423992 0.22775841589471402" />
            </geometry>
            <material name="Blue">
                <color rgba="0 0 1.0 1.0"/>
            </material>
        </visual>
        <collision>
            <origin xyz="0 0 0.11387920794735701" rpy="0 0 0"/>
            <geometry>
                <box size="0.2263642155711163 0.8971948235423992 0.22775841589471402" />
            </geometry>
        </collision>
    </link>
    <joint name="Link0_Link1" type="revolute">
       <parent link="Link0"/>
       <child  link="Link1"/>
       <origin rpy="0 0 0" xyz="0 0.4485974117711996 0.11387920794735701" />
       <axis xyz="0 1 0"/>
       <limit effort="0.0" lower="-3.14159" upper="3.14159" velocity="0.0"/>
    </joint>
    <link name="Link1">
        <inertial>
            <origin xyz="0 0.2730360301399195 0" rpy="0 0 0"/>
            <mass value="1" />
            <inertia ixx="100" ixy="0" ixz="0" iyy="100" iyz="0" izz="100" />
        </inertial>
        <visual>
            <origin xyz="0 0.2730360301399195 0" rpy="0 0 0"/>
            <geometry>
                <box size="0.5048012297630615 0.546072060279839 0.6069374575109735" />
            </geometry>
            <material name="Blue">
                <color rgba="0 0 1.0 1.0"/>
            </material>
        </visual>
        <collision>
            <origin xyz="0 0.2730360301399195 0" rpy="0 0 0"/>
            <geometry>
                <box size="0.5048012297630615 0.546072060279839 0.6069374575109735" />
            </geometry>
        </collision>
    </link>
    <joint name="Link1_Link2" type="revolute">
       <parent link="Link1"/>
       <child  link="Link2"/>
       <origin rpy="0 0 0" xyz="0.5048012297630615 0 0" />
       <axis xyz="0 0 1"/>
       <limit effort="0.0" lower="-3.14159" upper="3.14159" velocity="0.0"/>
    </joint>
    <link name="Link2">
        <inertial>
            <origin xyz="0.23658472451302864 0 0" rpy="0 0 0"/>
            <mass value="1" />
            <inertia ixx="100" ixy="0" ixz="0" iyy="100" iyz="0" izz="100" />
        </inertial>
        <visual>
            <origin xyz="0.23658472451302864 0 0" rpy="0 0 0"/>
            <geometry>
                <box size="0.4731694490260573 0.3594095536677611 0.561037156971885" />
            </geometry>
            <material name="Blue">
                <color rgba="0 0 1.0 1.0"/>
            </material>
        </visual>
        <collision>
            <origin xyz="0.23658472451302864 0 0" rpy="0 0 0"/>
            <geometry>
                <box size="0.4731694490260573 0.3594095536677611 0.561037156971885" />
            </geometry>
        </collision>
    </link>
</robot>