<robot name = "robot">
    <link name="Link0">
        <inertial>
            <origin xyz="0 0 0.27084470471705924" rpy="0 0 0"/>
            <mass value="1" />
            <inertia ixx="100" ixy="0" ixz="0" iyy="100" iyz="0" izz="100" />
        </inertial>
        <visual>
            <origin xyz="0 0 0.27084470471705924" rpy="0 0 0"/>
            <geometry>
                <box size="0.8959786021573459 0.8618938429338792 0.5416894094341185" />
            </geometry>
            <material name="Green">
                <color rgba="0 1.0 0 1.0"/>
            </material>
        </visual>
        <collision>
            <origin xyz="0 0 0.27084470471705924" rpy="0 0 0"/>
            <geometry>
                <box size="0.8959786021573459 0.8618938429338792 0.5416894094341185" />
            </geometry>
        </collision>
    </link>
    <joint name="Link0_Link1" type="revolute">
       <parent link="Link0"/>
       <child  link="Link1"/>
       <origin rpy="0 0 0" xyz="-0.44798930107867296 0 0.27084470471705924" />
       <axis xyz="1 0 0"/>
       <limit effort="0.0" lower="-3.14159" upper="3.14159" velocity="0.0"/>
    </joint>
    <link name="Link1">
        <inertial>
            <origin xyz="-0.229127422030534 0 0" rpy="0 0 0"/>
            <mass value="1" />
            <inertia ixx="100" ixy="0" ixz="0" iyy="100" iyz="0" izz="100" />
        </inertial>
        <visual>
            <origin xyz="-0.229127422030534 0 0" rpy="0 0 0"/>
            <geometry>
                <box size="0.458254844061068 0.6458436918894426 0.4224457383273563" />
            </geometry>
            <material name="Blue">
                <color rgba="0 0 1.0 1.0"/>
            </material>
        </visual>
        <collision>
            <origin xyz="-0.229127422030534 0 0" rpy="0 0 0"/>
            <geometry>
                <box size="0.458254844061068 0.6458436918894426 0.4224457383273563" />
            </geometry>
        </collision>
    </link>
    <joint name="Link1_Link2" type="revolute">
       <parent link="Link1"/>
       <child  link="Link2"/>
       <origin rpy="0 0 0" xyz="-0.458254844061068 0 0" />
       <axis xyz="0 0 1"/>
       <limit effort="0.0" lower="-3.14159" upper="3.14159" velocity="0.0"/>
    </joint>
    <link name="Link2">
        <inertial>
            <origin xyz="-0.17551386850163234 0 0" rpy="0 0 0"/>
            <mass value="1" />
            <inertia ixx="100" ixy="0" ixz="0" iyy="100" iyz="0" izz="100" />
        </inertial>
        <visual>
            <origin xyz="-0.17551386850163234 0 0" rpy="0 0 0"/>
            <geometry>
                <box size="0.3510277370032647 0.5155436874472117 0.6965131081450096" />
            </geometry>
            <material name="Green">
                <color rgba="0 1.0 0 1.0"/>
            </material>
        </visual>
        <collision>
            <origin xyz="-0.17551386850163234 0 0" rpy="0 0 0"/>
            <geometry>
                <box size="0.3510277370032647 0.5155436874472117 0.6965131081450096" />
            </geometry>
        </collision>
    </link>
    <joint name="Link2_Link3" type="revolute">
       <parent link="Link2"/>
       <child  link="Link3"/>
       <origin rpy="0 0 0" xyz="-0.17551386850163234 0 0.3482565540725048" />
       <axis xyz="0 0 1"/>
       <limit effort="0.0" lower="-3.14159" upper="3.14159" velocity="0.0"/>
    </joint>
    <link name="Link3">
        <inertial>
            <origin xyz="0 0 0.14859074505346143" rpy="0 0 0"/>
            <mass value="1" />
            <inertia ixx="100" ixy="0" ixz="0" iyy="100" iyz="0" izz="100" />
        </inertial>
        <visual>
            <origin xyz="0 0 0.14859074505346143" rpy="0 0 0"/>
            <geometry>
                <box size="0.46850766000501365 0.6056618571123071 0.29718149010692285" />
            </geometry>
            <material name="Blue">
                <color rgba="0 0 1.0 1.0"/>
            </material>
        </visual>
        <collision>
            <origin xyz="0 0 0.14859074505346143" rpy="0 0 0"/>
            <geometry>
                <box size="0.46850766000501365 0.6056618571123071 0.29718149010692285" />
            </geometry>
        </collision>
    </link>
    <joint name="Link1_Link4" type="revolute">
       <parent link="Link1"/>
       <child  link="Link4"/>
       <origin rpy="0 0 0" xyz="-0.229127422030534 0.3229218459447213 0" />
       <axis xyz="0 0 1"/>
       <limit effort="0.0" lower="-3.14159" upper="3.14159" velocity="0.0"/>
    </joint>
    <link name="Link4">
        <inertial>
            <origin xyz="0 0.3929594877912347 0" rpy="0 0 0"/>
            <mass value="1" />
            <inertia ixx="100" ixy="0" ixz="0" iyy="100" iyz="0" izz="100" />
        </inertial>
        <visual>
            <origin xyz="0 0.3929594877912347 0" rpy="0 0 0"/>
            <geometry>
                <box size="0.5146522052065066 0.7859189755824694 0.5158181773409272" />
            </geometry>
            <material name="Blue">
                <color rgba="0 0 1.0 1.0"/>
            </material>
        </visual>
        <collision>
            <origin xyz="0 0.3929594877912347 0" rpy="0 0 0"/>
            <geometry>
                <box size="0.5146522052065066 0.7859189755824694 0.5158181773409272" />
            </geometry>
        </collision>
    </link>
    <joint name="Link2_Link5" type="revolute">
       <parent link="Link2"/>
       <child  link="Link5"/>
       <origin rpy="0 0 0" xyz="-0.17551386850163234 0.25777184372360584 0" />
       <axis xyz="1 0 0"/>
       <limit effort="0.0" lower="-3.14159" upper="3.14159" velocity="0.0"/>
    </joint>
    <link name="Link5">
        <inertial>
            <origin xyz="0 0.34460037137971955 0" rpy="0 0 0"/>
            <mass value="1" />
            <inertia ixx="100" ixy="0" ixz="0" iyy="100" iyz="0" izz="100" />
        </inertial>
        <visual>
            <origin xyz="0 0.34460037137971955 0" rpy="0 0 0"/>
            <geometry>
                <box size="0.5078359040861453 0.6892007427594391 0.35607754399605673" />
            </geometry>
            <material name="Blue">
                <color rgba="0 0 1.0 1.0"/>
            </material>
        </visual>
        <collision>
            <origin xyz="0 0.34460037137971955 0" rpy="0 0 0"/>
            <geometry>
                <box size="0.5078359040861453 0.6892007427594391 0.35607754399605673" />
            </geometry>
        </collision>
    </link>
    <joint name="Link3_Link6" type="revolute">
       <parent link="Link3"/>
       <child  link="Link6"/>
       <origin rpy="0 0 0" xyz="0 -0.30283092855615357 0.14859074505346143" />
       <axis xyz="0 0 1"/>
       <limit effort="0.0" lower="-3.14159" upper="3.14159" velocity="0.0"/>
    </joint>
    <link name="Link6">
        <inertial>
            <origin xyz="0 -0.4228741460463563 0" rpy="0 0 0"/>
            <mass value="1" />
            <inertia ixx="100" ixy="0" ixz="0" iyy="100" iyz="0" izz="100" />
        </inertial>
        <visual>
            <origin xyz="0 -0.4228741460463563 0" rpy="0 0 0"/>
            <geometry>
                <box size="0.259960868356301 0.8457482920927126 0.599315078505348" />
            </geometry>
            <material name="Blue">
                <color rgba="0 0 1.0 1.0"/>
            </material>
        </visual>
        <collision>
            <origin xyz="0 -0.4228741460463563 0" rpy="0 0 0"/>
            <geometry>
                <box size="0.259960868356301 0.8457482920927126 0.599315078505348" />
            </geometry>
        </collision>
    </link>
</robot>