<robot name = "robot">
    <link name="Link0">
        <inertial>
            <origin xyz="0 0 0.3997699687443025" rpy="0 0 0"/>
            <mass value="1" />
            <inertia ixx="100" ixy="0" ixz="0" iyy="100" iyz="0" izz="100" />
        </inertial>
        <visual>
            <origin xyz="0 0 0.3997699687443025" rpy="0 0 0"/>
            <geometry>
                <box size="0.5070605398484369 0.25952966078017803 0.799539937488605" />
            </geometry>
            <material name="Green">
                <color rgba="0 1.0 0 1.0"/>
            </material>
        </visual>
        <collision>
            <origin xyz="0 0 0.3997699687443025" rpy="0 0 0"/>
            <geometry>
                <box size="0.5070605398484369 0.25952966078017803 0.799539937488605" />
            </geometry>
        </collision>
    </link>
    <joint name="Link0_Link1" type="revolute">
       <parent link="Link0"/>
       <child  link="Link1"/>
       <origin rpy="0 0 0" xyz="0.25353026992421845 0 0.3997699687443025" />
       <axis xyz="0 0 1"/>
       <limit effort="0.0" lower="-3.14159" upper="3.14159" velocity="0.0"/>
    </joint>
    <link name="Link1">
        <inertial>
            <origin xyz="0.4839598825030783 0 0" rpy="0 0 0"/>
            <mass value="1" />
            <inertia ixx="100" ixy="0" ixz="0" iyy="100" iyz="0" izz="100" />
        </inertial>
        <visual>
            <origin xyz="0.4839598825030783 0 0" rpy="0 0 0"/>
            <geometry>
                <box size="0.9679197650061566 0.5220258845468285 0.6103063864337632" />
            </geometry>
            <material name="Green">
                <color rgba="0 1.0 0 1.0"/>
            </material>
        </visual>
        <collision>
            <origin xyz="0.4839598825030783 0 0" rpy="0 0 0"/>
            <geometry>
                <box size="0.9679197650061566 0.5220258845468285 0.6103063864337632" />
            </geometry>
        </collision>
    </link>
    <joint name="Link1_Link2" type="revolute">
       <parent link="Link1"/>
       <child  link="Link2"/>
       <origin rpy="0 0 0" xyz="0.4839598825030783 0 0.3051531932168816" />
       <axis xyz="0 0 1"/>
       <limit effort="0.0" lower="-3.14159" upper="3.14159" velocity="0.0"/>
    </joint>
    <link name="Link2">
        <inertial>
            <origin xyz="0 0 0.27269662594827715" rpy="0 0 0"/>
            <mass value="1" />
            <inertia ixx="100" ixy="0" ixz="0" iyy="100" iyz="0" izz="100" />
        </inertial>
        <visual>
            <origin xyz="0 0 0.27269662594827715" rpy="0 0 0"/>
            <geometry>
                <box size="0.7266763841406068 0.8029595546087591 0.5453932518965543" />
            </geometry>
            <material name="Green">
                <color rgba="0 1.0 0 1.0"/>
            </material>
        </visual>
        <collision>
            <origin xyz="0 0 0.27269662594827715" rpy="0 0 0"/>
            <geometry>
                <box size="0.7266763841406068 0.8029595546087591 0.5453932518965543" />
            </geometry>
        </collision>
    </link>
</robot>