<robot name = "robot">
    <link name="Link0">
        <inertial>
            <origin xyz="0 0 0.3211262421059058" rpy="0 0 0"/>
            <mass value="1" />
            <inertia ixx="100" ixy="0" ixz="0" iyy="100" iyz="0" izz="100" />
        </inertial>
        <visual>
            <origin xyz="0 0 0.3211262421059058" rpy="0 0 0"/>
            <geometry>
                <box size="0.22839932313399836 0.638029631721083 0.6422524842118116" />
            </geometry>
            <material name="Green">
                <color rgba="0 1.0 0 1.0"/>
            </material>
        </visual>
        <collision>
            <origin xyz="0 0 0.3211262421059058" rpy="0 0 0"/>
            <geometry>
                <box size="0.22839932313399836 0.638029631721083 0.6422524842118116" />
            </geometry>
        </collision>
    </link>
    <joint name="Link0_Link1" type="revolute">
       <parent link="Link0"/>
       <child  link="Link1"/>
       <origin rpy="0 0 0" xyz="-0.11419966156699918 0 0.3211262421059058" />
       <axis xyz="0 0 1"/>
       <limit effort="0.0" lower="-3.14159" upper="3.14159" velocity="0.0"/>
    </joint>
    <link name="Link1">
        <inertial>
            <origin xyz="-0.3664400430457917 0 0" rpy="0 0 0"/>
            <mass value="1" />
            <inertia ixx="100" ixy="0" ixz="0" iyy="100" iyz="0" izz="100" />
        </inertial>
        <visual>
            <origin xyz="-0.3664400430457917 0 0" rpy="0 0 0"/>
            <geometry>
                <box size="0.7328800860915834 0.96260391302796 0.4526819818322387" />
            </geometry>
            <material name="Green">
                <color rgba="0 1.0 0 1.0"/>
            </material>
        </visual>
        <collision>
            <origin xyz="-0.3664400430457917 0 0" rpy="0 0 0"/>
            <geometry>
                <box size="0.7328800860915834 0.96260391302796 0.4526819818322387" />
            </geometry>
        </collision>
    </link>
    <joint name="Link1_Link2" type="revolute">
       <parent link="Link1"/>
       <child  link="Link2"/>
       <origin rpy="0 0 0" xyz="-0.3664400430457917 0 -0.22634099091611934" />
       <axis xyz="1 0 0"/>
       <limit effort="0.0" lower="-3.14159" upper="3.14159" velocity="0.0"/>
    </joint>
    <link name="Link2">
        <inertial>
            <origin xyz="0 0 -0.10345800707258027" rpy="0 0 0"/>
            <mass value="1" />
            <inertia ixx="100" ixy="0" ixz="0" iyy="100" iyz="0" izz="100" />
        </inertial>
        <visual>
            <origin xyz="0 0 -0.10345800707258027" rpy="0 0 0"/>
            <geometry>
                <box size="0.7161448595339017 0.8998771938261669 0.20691601414516053" />
            </geometry>
            <material name="Green">
                <color rgba="0 1.0 0 1.0"/>
            </material>
        </visual>
        <collision>
            <origin xyz="0 0 -0.10345800707258027" rpy="0 0 0"/>
            <geometry>
                <box size="0.7161448595339017 0.8998771938261669 0.20691601414516053" />
            </geometry>
        </collision>
    </link>
</robot>