<robot name = "robot">
    <link name="Link0">
        <inertial>
            <origin xyz="0 0 0.48006984206465964" rpy="0 0 0"/>
            <mass value="1" />
            <inertia ixx="100" ixy="0" ixz="0" iyy="100" iyz="0" izz="100" />
        </inertial>
        <visual>
            <origin xyz="0 0 0.48006984206465964" rpy="0 0 0"/>
            <geometry>
                <box size="0.8347666733602486 0.642417319121094 0.9601396841293193" />
            </geometry>
            <material name="Green">
                <color rgba="0 1.0 0 1.0"/>
            </material>
        </visual>
        <collision>
            <origin xyz="0 0 0.48006984206465964" rpy="0 0 0"/>
            <geometry>
                <box size="0.8347666733602486 0.642417319121094 0.9601396841293193" />
            </geometry>
        </collision>
    </link>
    <joint name="Link0_Link1" type="revolute">
       <parent link="Link0"/>
       <child  link="Link1"/>
       <origin rpy="0 0 0" xyz="0.4173833366801243 0 0.48006984206465964" />
       <axis xyz="1 0 0"/>
       <limit effort="0.0" lower="-3.14159" upper="3.14159" velocity="0.0"/>
    </joint>
    <link name="Link1">
        <inertial>
            <origin xyz="0.3207291979129444 0 0" rpy="0 0 0"/>
            <mass value="1" />
            <inertia ixx="100" ixy="0" ixz="0" iyy="100" iyz="0" izz="100" />
        </inertial>
        <visual>
            <origin xyz="0.3207291979129444 0 0" rpy="0 0 0"/>
            <geometry>
                <box size="0.6414583958258888 0.404748717874376 0.8540500100379929" />
            </geometry>
            <material name="Blue">
                <color rgba="0 0 1.0 1.0"/>
            </material>
        </visual>
        <collision>
            <origin xyz="0.3207291979129444 0 0" rpy="0 0 0"/>
            <geometry>
                <box size="0.6414583958258888 0.404748717874376 0.8540500100379929" />
            </geometry>
        </collision>
    </link>
    <joint name="Link0_Link2" type="revolute">
       <parent link="Link0"/>
       <child  link="Link2"/>
       <origin rpy="0 0 0" xyz="0 0 0.9601396841293193" />
       <axis xyz="0 0 1"/>
       <limit effort="0.0" lower="-3.14159" upper="3.14159" velocity="0.0"/>
    </joint>
    <link name="Link2">
        <inertial>
            <origin xyz="0 0 0.44402811454319147" rpy="0 0 0"/>
            <mass value="1" />
            <inertia ixx="100" ixy="0" ixz="0" iyy="100" iyz="0" izz="100" />
        </inertial>
        <visual>
            <origin xyz="0 0 0.44402811454319147" rpy="0 0 0"/>
            <geometry>
                <box size="0.7776022794098856 0.9353450061539159 0.8880562290863829" />
            </geometry>
            <material name="Green">
                <color rgba="0 1.0 0 1.0"/>
            </material>
        </visual>
        <collision>
            <origin xyz="0 0 0.44402811454319147" rpy="0 0 0"/>
            <geometry>
                <box size="0.7776022794098856 0.9353450061539159 0.8880562290863829" />
            </geometry>
        </collision>
    </link>
    <joint name="Link1_Link3" type="revolute">
       <parent link="Link1"/>
       <child  link="Link3"/>
       <origin rpy="0 0 0" xyz="0.3207291979129444 0 -0.42702500501899643" />
       <axis xyz="0 0 1"/>
       <limit effort="0.0" lower="-3.14159" upper="3.14159" velocity="0.0"/>
    </joint>
    <link name="Link3">
        <inertial>
            <origin xyz="0 0 -0.13440573562554975" rpy="0 0 0"/>
            <mass value="1" />
            <inertia ixx="100" ixy="0" ixz="0" iyy="100" iyz="0" izz="100" />
        </inertial>
        <visual>
            <origin xyz="0 0 -0.13440573562554975" rpy="0 0 0"/>
            <geometry>
                <box size="0.990175535294709 0.7435029115517007 0.2688114712510995" />
            </geometry>
            <material name="Green">
                <color rgba="0 1.0 0 1.0"/>
            </material>
        </visual>
        <collision>
            <origin xyz="0 0 -0.13440573562554975" rpy="0 0 0"/>
            <geometry>
                <box size="0.990175535294709 0.7435029115517007 0.2688114712510995" />
            </geometry>
        </collision>
    </link>
</robot>