<robot name = "robot">
    <link name="Link0">
        <inertial>
            <origin xyz="0 0 0.3074441859829474" rpy="0 0 0"/>
            <mass value="1" />
            <inertia ixx="100" ixy="0" ixz="0" iyy="100" iyz="0" izz="100" />
        </inertial>
        <visual>
            <origin xyz="0 0 0.3074441859829474" rpy="0 0 0"/>
            <geometry>
                <box size="0.7649328639568496 0.3080064582448036 0.6148883719658949" />
            </geometry>
            <material name="Green">
                <color rgba="0 1.0 0 1.0"/>
            </material>
        </visual>
        <collision>
            <origin xyz="0 0 0.3074441859829474" rpy="0 0 0"/>
            <geometry>
                <box size="0.7649328639568496 0.3080064582448036 0.6148883719658949" />
            </geometry>
        </collision>
    </link>
    <joint name="Link0_Link1" type="revolute">
       <parent link="Link0"/>
       <child  link="Link1"/>
       <origin rpy="0 0 0" xyz="0 -0.1540032291224018 0.3074441859829474" />
       <axis xyz="0 1 0"/>
       <limit effort="0.0" lower="-3.14159" upper="3.14159" velocity="0.0"/>
    </joint>
    <link name="Link1">
        <inertial>
            <origin xyz="0 -0.33707852861319704 0" rpy="0 0 0"/>
            <mass value="1" />
            <inertia ixx="100" ixy="0" ixz="0" iyy="100" iyz="0" izz="100" />
        </inertial>
        <visual>
            <origin xyz="0 -0.33707852861319704 0" rpy="0 0 0"/>
            <geometry>
                <box size="0.6145003296661014 0.6741570572263941 0.400902492093814" />
            </geometry>
            <material name="Blue">
                <color rgba="0 0 1.0 1.0"/>
            </material>
        </visual>
        <collision>
            <origin xyz="0 -0.33707852861319704 0" rpy="0 0 0"/>
            <geometry>
                <box size="0.6145003296661014 0.6741570572263941 0.400902492093814" />
            </geometry>
        </collision>
    </link>
    <joint name="Link0_Link2" type="revolute">
       <parent link="Link0"/>
       <child  link="Link2"/>
       <origin rpy="0 0 0" xyz="0 0.1540032291224018 0.3074441859829474" />
       <axis xyz="0 0 1"/>
       <limit effort="0.0" lower="-3.14159" upper="3.14159" velocity="0.0"/>
    </joint>
    <link name="Link2">
        <inertial>
            <origin xyz="0 0.4038948936333414 0" rpy="0 0 0"/>
            <mass value="1" />
            <inertia ixx="100" ixy="0" ixz="0" iyy="100" iyz="0" izz="100" />
        </inertial>
        <visual>
            <origin xyz="0 0.4038948936333414 0" rpy="0 0 0"/>
            <geometry>
                <box size="0.5838322747566276 0.8077897872666828 0.842851424928341" />
            </geometry>
            <material name="Green">
                <color rgba="0 1.0 0 1.0"/>
            </material>
        </visual>
        <collision>
            <origin xyz="0 0.4038948936333414 0" rpy="0 0 0"/>
            <geometry>
                <box size="0.5838322747566276 0.8077897872666828 0.842851424928341" />
            </geometry>
        </collision>
    </link>
    <joint name="Link2_Link3" type="revolute">
       <parent link="Link2"/>
       <child  link="Link3"/>
       <origin rpy="0 0 0" xyz="0 0.4038948936333414 0.4214257124641705" />
       <axis xyz="1 0 0"/>
       <limit effort="0.0" lower="-3.14159" upper="3.14159" velocity="0.0"/>
    </joint>
    <link name="Link3">
        <inertial>
            <origin xyz="0 0 0.27638676562611564" rpy="0 0 0"/>
            <mass value="1" />
            <inertia ixx="100" ixy="0" ixz="0" iyy="100" iyz="0" izz="100" />
        </inertial>
        <visual>
            <origin xyz="0 0 0.27638676562611564" rpy="0 0 0"/>
            <geometry>
                <box size="0.4853632239257592 0.5106425293465349 0.5527735312522313" />
            </geometry>
            <material name="Blue">
                <color rgba="0 0 1.0 1.0"/>
            </material>
        </visual>
        <collision>
            <origin xyz="0 0 0.27638676562611564" rpy="0 0 0"/>
            <geometry>
                <box size="0.4853632239257592 0.5106425293465349 0.5527735312522313" />
            </geometry>
        </collision>
    </link>
    <joint name="Link0_Link4" type="revolute">
       <parent link="Link0"/>
       <child  link="Link4"/>
       <origin rpy="0 0 0" xyz="-0.3824664319784248 0 0.3074441859829474" />
       <axis xyz="0 0 1"/>
       <limit effort="0.0" lower="-3.14159" upper="3.14159" velocity="0.0"/>
    </joint>
    <link name="Link4">
        <inertial>
            <origin xyz="-0.1682274521713732 0 0" rpy="0 0 0"/>
            <mass value="1" />
            <inertia ixx="100" ixy="0" ixz="0" iyy="100" iyz="0" izz="100" />
        </inertial>
        <visual>
            <origin xyz="-0.1682274521713732 0 0" rpy="0 0 0"/>
            <geometry>
                <box size="0.3364549043427464 0.3099152540121172 0.27343228008950143" />
            </geometry>
            <material name="Blue">
                <color rgba="0 0 1.0 1.0"/>
            </material>
        </visual>
        <collision>
            <origin xyz="-0.1682274521713732 0 0" rpy="0 0 0"/>
            <geometry>
                <box size="0.3364549043427464 0.3099152540121172 0.27343228008950143" />
            </geometry>
        </collision>
    </link>
    <joint name="Link0_Link5" type="revolute">
       <parent link="Link0"/>
       <child  link="Link5"/>
       <origin rpy="0 0 0" xyz="0.3824664319784248 0 0.3074441859829474" />
       <axis xyz="1 0 0"/>
       <limit effort="0.0" lower="-3.14159" upper="3.14159" velocity="0.0"/>
    </joint>
    <link name="Link5">
        <inertial>
            <origin xyz="0.3145984681926943 0 0" rpy="0 0 0"/>
            <mass value="1" />
            <inertia ixx="100" ixy="0" ixz="0" iyy="100" iyz="0" izz="100" />
        </inertial>
        <visual>
            <origin xyz="0.3145984681926943 0 0" rpy="0 0 0"/>
            <geometry>
                <box size="0.6291969363853886 0.6908635309907953 0.739399056848095" />
            </geometry>
            <material name="Blue">
                <color rgba="0 0 1.0 1.0"/>
            </material>
        </visual>
        <collision>
            <origin xyz="0.3145984681926943 0 0" rpy="0 0 0"/>
            <geometry>
                <box size="0.6291969363853886 0.6908635309907953 0.739399056848095" />
            </geometry>
        </collision>
    </link>
    <joint name="Link3_Link6" type="revolute">
       <parent link="Link3"/>
       <child  link="Link6"/>
       <origin rpy="0 0 0" xyz="0 0 0.5527735312522313" />
       <axis xyz="1 0 0"/>
       <limit effort="0.0" lower="-3.14159" upper="3.14159" velocity="0.0"/>
    </joint>
    <link name="Link6">
        <inertial>
            <origin xyz="0 0 0.46511975975578246" rpy="0 0 0"/>
            <mass value="1" />
            <inertia ixx="100" ixy="0" ixz="0" iyy="100" iyz="0" izz="100" />
        </inertial>
        <visual>
            <origin xyz="0 0 0.46511975975578246" rpy="0 0 0"/>
            <geometry>
                <box size="0.5265648963032281 0.40135595073455543 0.9302395195115649" />
            </geometry>
            <material name="Blue">
                <color rgba="0 0 1.0 1.0"/>
            </material>
        </visual>
        <collision>
            <origin xyz="0 0 0.46511975975578246" rpy="0 0 0"/>
            <geometry>
                <box size="0.5265648963032281 0.40135595073455543 0.9302395195115649" />
            </geometry>
        </collision>
    </link>
</robot>