<robot name = "robot">
    <link name="Link0">
        <inertial>
            <origin xyz="0 0 0.3250148366749289" rpy="0 0 0"/>
            <mass value="1" />
            <inertia ixx="100" ixy="0" ixz="0" iyy="100" iyz="0" izz="100" />
        </inertial>
        <visual>
            <origin xyz="0 0 0.3250148366749289" rpy="0 0 0"/>
            <geometry>
                <box size="0.38525349833367833 0.9301210024807076 0.6500296733498578" />
            </geometry>
            <material name="Green">
                <color rgba="0 1.0 0 1.0"/>
            </material>
        </visual>
        <collision>
            <origin xyz="0 0 0.3250148366749289" rpy="0 0 0"/>
            <geometry>
                <box size="0.38525349833367833 0.9301210024807076 0.6500296733498578" />
            </geometry>
        </collision>
    </link>
    <joint name="Link0_Link1" type="revolute">
       <parent link="Link0"/>
       <child  link="Link1"/>
       <origin rpy="0 0 0" xyz="0.19262674916683917 0 0.3250148366749289" />
       <axis xyz="0 1 0"/>
       <limit effort="0.0" lower="-3.14159" upper="3.14159" velocity="0.0"/>
    </joint>
    <link name="Link1">
        <inertial>
            <origin xyz="0.19574246788721186 0 0" rpy="0 0 0"/>
            <mass value="1" />
            <inertia ixx="100" ixy="0" ixz="0" iyy="100" iyz="0" izz="100" />
        </inertial>
        <visual>
            <origin xyz="0.19574246788721186 0 0" rpy="0 0 0"/>
            <geometry>
                <box size="0.3914849357744237 0.34696138609777205 0.22272640988659964" />
            </geometry>
            <material name="Blue">
                <color rgba="0 0 1.0 1.0"/>
            </material>
        </visual>
        <collision>
            <origin xyz="0.19574246788721186 0 0" rpy="0 0 0"/>
            <geometry>
                <box size="0.3914849357744237 0.34696138609777205 0.22272640988659964" />
            </geometry>
        </collision>
    </link>
    <joint name="Link1_Link2" type="revolute">
       <parent link="Link1"/>
       <child  link="Link2"/>
       <origin rpy="0 0 0" xyz="0.19574246788721186 0 -0.11136320494329982" />
       <axis xyz="1 0 0"/>
       <limit effort="0.0" lower="-3.14159" upper="3.14159" velocity="0.0"/>
    </joint>
    <link name="Link2">
        <inertial>
            <origin xyz="0 0 -0.1374015892584474" rpy="0 0 0"/>
            <mass value="1" />
            <inertia ixx="100" ixy="0" ixz="0" iyy="100" iyz="0" izz="100" />
        </inertial>
        <visual>
            <origin xyz="0 0 -0.1374015892584474" rpy="0 0 0"/>
            <geometry>
                <box size="0.5973147674477637 0.4028412338520968 0.2748031785168948" />
            </geometry>
            <material name="Green">
                <color rgba="0 1.0 0 1.0"/>
            </material>
        </visual>
        <collision>
            <origin xyz="0 0 -0.1374015892584474" rpy="0 0 0"/>
            <geometry>
                <box size="0.5973147674477637 0.4028412338520968 0.2748031785168948" />
            </geometry>
        </collision>
    </link>
    <joint name="Link2_Link3" type="revolute">
       <parent link="Link2"/>
       <child  link="Link3"/>
       <origin rpy="0 0 0" xyz="0 -0.2014206169260484 -0.1374015892584474" />
       <axis xyz="0 1 0"/>
       <limit effort="0.0" lower="-3.14159" upper="3.14159" velocity="0.0"/>
    </joint>
    <link name="Link3">
        <inertial>
            <origin xyz="0 -0.4496233930911758 0" rpy="0 0 0"/>
            <mass value="1" />
            <inertia ixx="100" ixy="0" ixz="0" iyy="100" iyz="0" izz="100" />
        </inertial>
        <visual>
            <origin xyz="0 -0.4496233930911758 0" rpy="0 0 0"/>
            <geometry>
                <box size="0.8581247945853288 0.8992467861823517 0.5963335964792653" />
            </geometry>
            <material name="Blue">
                <color rgba="0 0 1.0 1.0"/>
            </material>
        </visual>
        <collision>
            <origin xyz="0 -0.4496233930911758 0" rpy="0 0 0"/>
            <geometry>
                <box size="0.8581247945853288 0.8992467861823517 0.5963335964792653" />
            </geometry>
        </collision>
    </link>
    <joint name="Link0_Link4" type="revolute">
       <parent link="Link0"/>
       <child  link="Link4"/>
       <origin rpy="0 0 0" xyz="0 0 0.6500296733498578" />
       <axis xyz="0 1 0"/>
       <limit effort="0.0" lower="-3.14159" upper="3.14159" velocity="0.0"/>
    </joint>
    <link name="Link4">
        <inertial>
            <origin xyz="0 0 0.16971478676775537" rpy="0 0 0"/>
            <mass value="1" />
            <inertia ixx="100" ixy="0" ixz="0" iyy="100" iyz="0" izz="100" />
        </inertial>
        <visual>
            <origin xyz="0 0 0.16971478676775537" rpy="0 0 0"/>
            <geometry>
                <box size="0.23950279443514433 0.8692512000022898 0.33942957353551073" />
            </geometry>
            <material name="Blue">
                <color rgba="0 0 1.0 1.0"/>
            </material>
        </visual>
        <collision>
            <origin xyz="0 0 0.16971478676775537" rpy="0 0 0"/>
            <geometry>
                <box size="0.23950279443514433 0.8692512000022898 0.33942957353551073" />
            </geometry>
        </collision>
    </link>
    <joint name="Link2_Link5" type="revolute">
       <parent link="Link2"/>
       <child  link="Link5"/>
       <origin rpy="0 0 0" xyz="-0.29865738372388184 0 -0.1374015892584474" />
       <axis xyz="1 0 0"/>
       <limit effort="0.0" lower="-3.14159" upper="3.14159" velocity="0.0"/>
    </joint>
    <link name="Link5">
        <inertial>
            <origin xyz="-0.16499936623832206 0 0" rpy="0 0 0"/>
            <mass value="1" />
            <inertia ixx="100" ixy="0" ixz="0" iyy="100" iyz="0" izz="100" />
        </inertial>
        <visual>
            <origin xyz="-0.16499936623832206 0 0" rpy="0 0 0"/>
            <geometry>
                <box size="0.32999873247664413 0.6566291028048847 0.7013391612201143" />
            </geometry>
            <material name="Blue">
                <color rgba="0 0 1.0 1.0"/>
            </material>
        </visual>
        <collision>
            <origin xyz="-0.16499936623832206 0 0" rpy="0 0 0"/>
            <geometry>
                <box size="0.32999873247664413 0.6566291028048847 0.7013391612201143" />
            </geometry>
        </collision>
    </link>
    <joint name="Link4_Link6" type="revolute">
       <parent link="Link4"/>
       <child  link="Link6"/>
       <origin rpy="0 0 0" xyz="0.11975139721757216 0 0.16971478676775537" />
       <axis xyz="1 0 0"/>
       <limit effort="0.0" lower="-3.14159" upper="3.14159" velocity="0.0"/>
    </joint>
    <link name="Link6">
        <inertial>
            <origin xyz="0.20002504702380064 0 0" rpy="0 0 0"/>
            <mass value="1" />
            <inertia ixx="100" ixy="0" ixz="0" iyy="100" iyz="0" izz="100" />
        </inertial>
        <visual>
            <origin xyz="0.20002504702380064 0 0" rpy="0 0 0"/>
            <geometry>
                <box size="0.4000500940476013 0.4013137733325919 0.8502198124232994" />
            </geometry>
            <material name="Blue">
                <color rgba="0 0 1.0 1.0"/>
            </material>
        </visual>
        <collision>
            <origin xyz="0.20002504702380064 0 0" rpy="0 0 0"/>
            <geometry>
                <box size="0.4000500940476013 0.4013137733325919 0.8502198124232994" />
            </geometry>
        </collision>
    </link>
</robot>