<robot name = "robot">
    <link name="Link0">
        <inertial>
            <origin xyz="0 0 0.47412895254251297" rpy="0 0 0"/>
            <mass value="1" />
            <inertia ixx="100" ixy="0" ixz="0" iyy="100" iyz="0" izz="100" />
        </inertial>
        <visual>
            <origin xyz="0 0 0.47412895254251297" rpy="0 0 0"/>
            <geometry>
                <box size="0.8962544266781778 0.9305835131628204 0.9482579050850259" />
            </geometry>
            <material name="Blue">
                <color rgba="0 0 1.0 1.0"/>
            </material>
        </visual>
        <collision>
            <origin xyz="0 0 0.47412895254251297" rpy="0 0 0"/>
            <geometry>
                <box size="0.8962544266781778 0.9305835131628204 0.9482579050850259" />
            </geometry>
        </collision>
    </link>
    <joint name="Link0_Link1" type="revolute">
       <parent link="Link0"/>
       <child  link="Link1"/>
       <origin rpy="0 0 0" xyz="0 -0.4652917565814102 0.47412895254251297" />
       <axis xyz="1 0 0"/>
       <limit effort="0.0" lower="-3.14159" upper="3.14159" velocity="0.0"/>
    </joint>
    <link name="Link1">
        <inertial>
            <origin xyz="0 -0.3144275535904776 0" rpy="0 0 0"/>
            <mass value="1" />
            <inertia ixx="100" ixy="0" ixz="0" iyy="100" iyz="0" izz="100" />
        </inertial>
        <visual>
            <origin xyz="0 -0.3144275535904776 0" rpy="0 0 0"/>
            <geometry>
                <box size="0.5159493384318312 0.6288551071809552 0.973747269710366" />
            </geometry>
            <material name="Blue">
                <color rgba="0 0 1.0 1.0"/>
            </material>
        </visual>
        <collision>
            <origin xyz="0 -0.3144275535904776 0" rpy="0 0 0"/>
            <geometry>
                <box size="0.5159493384318312 0.6288551071809552 0.973747269710366" />
            </geometry>
        </collision>
    </link>
    <joint name="Link0_Link2" type="revolute">
       <parent link="Link0"/>
       <child  link="Link2"/>
       <origin rpy="0 0 0" xyz="0 0 0.9482579050850259" />
       <axis xyz="0 1 0"/>
       <limit effort="0.0" lower="-3.14159" upper="3.14159" velocity="0.0"/>
    </joint>
    <link name="Link2">
        <inertial>
            <origin xyz="0 0 0.1614637636279928" rpy="0 0 0"/>
            <mass value="1" />
            <inertia ixx="100" ixy="0" ixz="0" iyy="100" iyz="0" izz="100" />
        </inertial>
        <visual>
            <origin xyz="0 0 0.1614637636279928" rpy="0 0 0"/>
            <geometry>
                <box size="0.8238933405985807 0.9125890881022025 0.3229275272559856" />
            </geometry>
            <material name="Green">
                <color rgba="0 1.0 0 1.0"/>
            </material>
        </visual>
        <collision>
            <origin xyz="0 0 0.1614637636279928" rpy="0 0 0"/>
            <geometry>
                <box size="0.8238933405985807 0.9125890881022025 0.3229275272559856" />
            </geometry>
        </collision>
    </link>
    <joint name="Link1_Link3" type="revolute">
       <parent link="Link1"/>
       <child  link="Link3"/>
       <origin rpy="0 0 0" xyz="0 -0.3144275535904776 -0.486873634855183" />
       <axis xyz="1 0 0"/>
       <limit effort="0.0" lower="-3.14159" upper="3.14159" velocity="0.0"/>
    </joint>
    <link name="Link3">
        <inertial>
            <origin xyz="0 0 -0.47107890177446754" rpy="0 0 0"/>
            <mass value="1" />
            <inertia ixx="100" ixy="0" ixz="0" iyy="100" iyz="0" izz="100" />
        </inertial>
        <visual>
            <origin xyz="0 0 -0.47107890177446754" rpy="0 0 0"/>
            <geometry>
                <box size="0.2832035550972955 0.8983869001768545 0.9421578035489351" />
            </geometry>
            <material name="Green">
                <color rgba="0 1.0 0 1.0"/>
            </material>
        </visual>
        <collision>
            <origin xyz="0 0 -0.47107890177446754" rpy="0 0 0"/>
            <geometry>
                <box size="0.2832035550972955 0.8983869001768545 0.9421578035489351" />
            </geometry>
        </collision>
    </link>
    <joint name="Link0_Link4" type="revolute">
       <parent link="Link0"/>
       <child  link="Link4"/>
       <origin rpy="0 0 0" xyz="0 0.4652917565814102 0.47412895254251297" />
       <axis xyz="0 1 0"/>
       <limit effort="0.0" lower="-3.14159" upper="3.14159" velocity="0.0"/>
    </joint>
    <link name="Link4">
        <inertial>
            <origin xyz="0 0.3845884860556368 0" rpy="0 0 0"/>
            <mass value="1" />
            <inertia ixx="100" ixy="0" ixz="0" iyy="100" iyz="0" izz="100" />
        </inertial>
        <visual>
            <origin xyz="0 0.3845884860556368 0" rpy="0 0 0"/>
            <geometry>
                <box size="0.7337882999578238 0.7691769721112736 0.8606301076345833" />
            </geometry>
            <material name="Green">
                <color rgba="0 1.0 0 1.0"/>
            </material>
        </visual>
        <collision>
            <origin xyz="0 0.3845884860556368 0" rpy="0 0 0"/>
            <geometry>
                <box size="0.7337882999578238 0.7691769721112736 0.8606301076345833" />
            </geometry>
        </collision>
    </link>
    <joint name="Link4_Link5" type="revolute">
       <parent link="Link4"/>
       <child  link="Link5"/>
       <origin rpy="0 0 0" xyz="0 0.3845884860556368 0.4303150538172916" />
       <axis xyz="0 0 1"/>
       <limit effort="0.0" lower="-3.14159" upper="3.14159" velocity="0.0"/>
    </joint>
    <link name="Link5">
        <inertial>
            <origin xyz="0 0 0.3662572096679565" rpy="0 0 0"/>
            <mass value="1" />
            <inertia ixx="100" ixy="0" ixz="0" iyy="100" iyz="0" izz="100" />
        </inertial>
        <visual>
            <origin xyz="0 0 0.3662572096679565" rpy="0 0 0"/>
            <geometry>
                <box size="0.29669123636509975 0.5173055238260309 0.732514419335913" />
            </geometry>
            <material name="Blue">
                <color rgba="0 0 1.0 1.0"/>
            </material>
        </visual>
        <collision>
            <origin xyz="0 0 0.3662572096679565" rpy="0 0 0"/>
            <geometry>
                <box size="0.29669123636509975 0.5173055238260309 0.732514419335913" />
            </geometry>
        </collision>
    </link>
</robot>