<robot name = "robot">
    <link name="Link0">
        <inertial>
            <origin xyz="0 0 0.11483579829166111" rpy="0 0 0"/>
            <mass value="1" />
            <inertia ixx="100" ixy="0" ixz="0" iyy="100" iyz="0" izz="100" />
        </inertial>
        <visual>
            <origin xyz="0 0 0.11483579829166111" rpy="0 0 0"/>
            <geometry>
                <box size="0.6787613042713205 0.8419545116554628 0.22967159658332223" />
            </geometry>
            <material name="Green">
                <color rgba="0 1.0 0 1.0"/>
            </material>
        </visual>
        <collision>
            <origin xyz="0 0 0.11483579829166111" rpy="0 0 0"/>
            <geometry>
                <box size="0.6787613042713205 0.8419545116554628 0.22967159658332223" />
            </geometry>
        </collision>
    </link>
    <joint name="Link0_Link1" type="revolute">
       <parent link="Link0"/>
       <child  link="Link1"/>
       <origin rpy="0 0 0" xyz="0.33938065213566027 0 0.11483579829166111" />
       <axis xyz="0 0 1"/>
       <limit effort="0.0" lower="-3.14159" upper="3.14159" velocity="0.0"/>
    </joint>
    <link name="Link1">
        <inertial>
            <origin xyz="0.481335112402983 0 0" rpy="0 0 0"/>
            <mass value="1" />
            <inertia ixx="100" ixy="0" ixz="0" iyy="100" iyz="0" izz="100" />
        </inertial>
        <visual>
            <origin xyz="0.481335112402983 0 0" rpy="0 0 0"/>
            <geometry>
                <box size="0.962670224805966 0.2163240907823754 0.6113734922886955" />
            </geometry>
            <material name="Blue">
                <color rgba="0 0 1.0 1.0"/>
            </material>
        </visual>
        <collision>
            <origin xyz="0.481335112402983 0 0" rpy="0 0 0"/>
            <geometry>
                <box size="0.962670224805966 0.2163240907823754 0.6113734922886955" />
            </geometry>
        </collision>
    </link>
    <joint name="Link1_Link2" type="revolute">
       <parent link="Link1"/>
       <child  link="Link2"/>
       <origin rpy="0 0 0" xyz="0.481335112402983 0 0.30568674614434777" />
       <axis xyz="1 0 0"/>
       <limit effort="0.0" lower="-3.14159" upper="3.14159" velocity="0.0"/>
    </joint>
    <link name="Link2">
        <inertial>
            <origin xyz="0 0 0.2819430631444412" rpy="0 0 0"/>
            <mass value="1" />
            <inertia ixx="100" ixy="0" ixz="0" iyy="100" iyz="0" izz="100" />
        </inertial>
        <visual>
            <origin xyz="0 0 0.2819430631444412" rpy="0 0 0"/>
            <geometry>
                <box size="0.21544117221213357 0.5474208366786013 0.5638861262888824" />
            </geometry>
            <material name="Green">
                <color rgba="0 1.0 0 1.0"/>
            </material>
        </visual>
        <collision>
            <origin xyz="0 0 0.2819430631444412" rpy="0 0 0"/>
            <geometry>
                <box size="0.21544117221213357 0.5474208366786013 0.5638861262888824" />
            </geometry>
        </collision>
    </link>
    <joint name="Link2_Link3" type="revolute">
       <parent link="Link2"/>
       <child  link="Link3"/>
       <origin rpy="0 0 0" xyz="0 0 0.5638861262888824" />
       <axis xyz="0 1 0"/>
       <limit effort="0.0" lower="-3.14159" upper="3.14159" velocity="0.0"/>
    </joint>
    <link name="Link3">
        <inertial>
            <origin xyz="0 0 0.40324908543432425" rpy="0 0 0"/>
            <mass value="1" />
            <inertia ixx="100" ixy="0" ixz="0" iyy="100" iyz="0" izz="100" />
        </inertial>
        <visual>
            <origin xyz="0 0 0.40324908543432425" rpy="0 0 0"/>
            <geometry>
                <box size="0.6118065905779686 0.9357109318446313 0.8064981708686485" />
            </geometry>
            <material name="Green">
                <color rgba="0 1.0 0 1.0"/>
            </material>
        </visual>
        <collision>
            <origin xyz="0 0 0.40324908543432425" rpy="0 0 0"/>
            <geometry>
                <box size="0.6118065905779686 0.9357109318446313 0.8064981708686485" />
            </geometry>
        </collision>
    </link>
</robot>