<robot name = "robot">
    <link name="Link0">
        <inertial>
            <origin xyz="0 0 0.49109713945299116" rpy="0 0 0"/>
            <mass value="1" />
            <inertia ixx="100" ixy="0" ixz="0" iyy="100" iyz="0" izz="100" />
        </inertial>
        <visual>
            <origin xyz="0 0 0.49109713945299116" rpy="0 0 0"/>
            <geometry>
                <box size="0.7366512833284635 0.5678325058203894 0.9821942789059823" />
            </geometry>
            <material name="Green">
                <color rgba="0 1.0 0 1.0"/>
            </material>
        </visual>
        <collision>
            <origin xyz="0 0 0.49109713945299116" rpy="0 0 0"/>
            <geometry>
                <box size="0.7366512833284635 0.5678325058203894 0.9821942789059823" />
            </geometry>
        </collision>
    </link>
    <joint name="Link0_Link1" type="revolute">
       <parent link="Link0"/>
       <child  link="Link1"/>
       <origin rpy="0 0 0" xyz="0 0.2839162529101947 0.49109713945299116" />
       <axis xyz="1 0 0"/>
       <limit effort="0.0" lower="-3.14159" upper="3.14159" velocity="0.0"/>
    </joint>
    <link name="Link1">
        <inertial>
            <origin xyz="0 0.10780740148879114 0" rpy="0 0 0"/>
            <mass value="1" />
            <inertia ixx="100" ixy="0" ixz="0" iyy="100" iyz="0" izz="100" />
        </inertial>
        <visual>
            <origin xyz="0 0.10780740148879114 0" rpy="0 0 0"/>
            <geometry>
                <box size="0.2804289834173601 0.2156148029775823 0.820561870822665" />
            </geometry>
            <material name="Blue">
                <color rgba="0 0 1.0 1.0"/>
            </material>
        </visual>
        <collision>
            <origin xyz="0 0.10780740148879114 0" rpy="0 0 0"/>
            <geometry>
                <box size="0.2804289834173601 0.2156148029775823 0.820561870822665" />
            </geometry>
        </collision>
    </link>
    <joint name="Link0_Link2" type="revolute">
       <parent link="Link0"/>
       <child  link="Link2"/>
       <origin rpy="0 0 0" xyz="0 -0.2839162529101947 0.49109713945299116" />
       <axis xyz="0 1 0"/>
       <limit effort="0.0" lower="-3.14159" upper="3.14159" velocity="0.0"/>
    </joint>
    <link name="Link2">
        <inertial>
            <origin xyz="0 -0.14247091120234678 0" rpy="0 0 0"/>
            <mass value="1" />
            <inertia ixx="100" ixy="0" ixz="0" iyy="100" iyz="0" izz="100" />
        </inertial>
        <visual>
            <origin xyz="0 -0.14247091120234678 0" rpy="0 0 0"/>
            <geometry>
                <box size="0.6873645906128476 0.28494182240469357 0.9959733930863393" />
            </geometry>
            <material name="Green">
                <color rgba="0 1.0 0 1.0"/>
            </material>
        </visual>
        <collision>
            <origin xyz="0 -0.14247091120234678 0" rpy="0 0 0"/>
            <geometry>
                <box size="0.6873645906128476 0.28494182240469357 0.9959733930863393" />
            </geometry>
        </collision>
    </link>
    <joint name="Link0_Link3" type="revolute">
       <parent link="Link0"/>
       <child  link="Link3"/>
       <origin rpy="0 0 0" xyz="-0.36832564166423176 0 0.49109713945299116" />
       <axis xyz="1 0 0"/>
       <limit effort="0.0" lower="-3.14159" upper="3.14159" velocity="0.0"/>
    </joint>
    <link name="Link3">
        <inertial>
            <origin xyz="-0.35207164567060756 0 0" rpy="0 0 0"/>
            <mass value="1" />
            <inertia ixx="100" ixy="0" ixz="0" iyy="100" iyz="0" izz="100" />
        </inertial>
        <visual>
            <origin xyz="-0.35207164567060756 0 0" rpy="0 0 0"/>
            <geometry>
                <box size="0.7041432913412151 0.5370380803042596 0.2337421115920451" />
            </geometry>
            <material name="Green">
                <color rgba="0 1.0 0 1.0"/>
            </material>
        </visual>
        <collision>
            <origin xyz="-0.35207164567060756 0 0" rpy="0 0 0"/>
            <geometry>
                <box size="0.7041432913412151 0.5370380803042596 0.2337421115920451" />
            </geometry>
        </collision>
    </link>
</robot>