<robot name = "robot">
    <link name="Link0">
        <inertial>
            <origin xyz="0 0 0.4728547826267998" rpy="0 0 0"/>
            <mass value="1" />
            <inertia ixx="100" ixy="0" ixz="0" iyy="100" iyz="0" izz="100" />
        </inertial>
        <visual>
            <origin xyz="0 0 0.4728547826267998" rpy="0 0 0"/>
            <geometry>
                <box size="0.297760444824404 0.253481790344543 0.9457095652535996" />
            </geometry>
            <material name="Green">
                <color rgba="0 1.0 0 1.0"/>
            </material>
        </visual>
        <collision>
            <origin xyz="0 0 0.4728547826267998" rpy="0 0 0"/>
            <geometry>
                <box size="0.297760444824404 0.253481790344543 0.9457095652535996" />
            </geometry>
        </collision>
    </link>
    <joint name="Link0_Link1" type="revolute">
       <parent link="Link0"/>
       <child  link="Link1"/>
       <origin rpy="0 0 0" xyz="0 -0.1267408951722715 0.4728547826267998" />
       <axis xyz="0 1 0"/>
       <limit effort="0.0" lower="-3.14159" upper="3.14159" velocity="0.0"/>
    </joint>
    <link name="Link1">
        <inertial>
            <origin xyz="0 -0.31679285935149115 0" rpy="0 0 0"/>
            <mass value="1" />
            <inertia ixx="100" ixy="0" ixz="0" iyy="100" iyz="0" izz="100" />
        </inertial>
        <visual>
            <origin xyz="0 -0.31679285935149115 0" rpy="0 0 0"/>
            <geometry>
                <box size="0.991760062055044 0.6335857187029823 0.9211454476949468" />
            </geometry>
            <material name="Blue">
                <color rgba="0 0 1.0 1.0"/>
            </material>
        </visual>
        <collision>
            <origin xyz="0 -0.31679285935149115 0" rpy="0 0 0"/>
            <geometry>
                <box size="0.991760062055044 0.6335857187029823 0.9211454476949468" />
            </geometry>
        </collision>
    </link>
    <joint name="Link0_Link2" type="revolute">
       <parent link="Link0"/>
       <child  link="Link2"/>
       <origin rpy="0 0 0" xyz="0 0 0.9457095652535996" />
       <axis xyz="0 1 0"/>
       <limit effort="0.0" lower="-3.14159" upper="3.14159" velocity="0.0"/>
    </joint>
    <link name="Link2">
        <inertial>
            <origin xyz="0 0 0.3522869999961624" rpy="0 0 0"/>
            <mass value="1" />
            <inertia ixx="100" ixy="0" ixz="0" iyy="100" iyz="0" izz="100" />
        </inertial>
        <visual>
            <origin xyz="0 0 0.3522869999961624" rpy="0 0 0"/>
            <geometry>
                <box size="0.9927024459243221 0.800034749272597 0.7045739999923248" />
            </geometry>
            <material name="Blue">
                <color rgba="0 0 1.0 1.0"/>
            </material>
        </visual>
        <collision>
            <origin xyz="0 0 0.3522869999961624" rpy="0 0 0"/>
            <geometry>
                <box size="0.9927024459243221 0.800034749272597 0.7045739999923248" />
            </geometry>
        </collision>
    </link>
    <joint name="Link1_Link3" type="revolute">
       <parent link="Link1"/>
       <child  link="Link3"/>
       <origin rpy="0 0 0" xyz="0 -0.6335857187029823 0" />
       <axis xyz="0 1 0"/>
       <limit effort="0.0" lower="-3.14159" upper="3.14159" velocity="0.0"/>
    </joint>
    <link name="Link3">
        <inertial>
            <origin xyz="0 -0.18727201152070322 0" rpy="0 0 0"/>
            <mass value="1" />
            <inertia ixx="100" ixy="0" ixz="0" iyy="100" iyz="0" izz="100" />
        </inertial>
        <visual>
            <origin xyz="0 -0.18727201152070322 0" rpy="0 0 0"/>
            <geometry>
                <box size="0.4572163427382339 0.37454402304140644 0.46641514169863063" />
            </geometry>
            <material name="Green">
                <color rgba="0 1.0 0 1.0"/>
            </material>
        </visual>
        <collision>
            <origin xyz="0 -0.18727201152070322 0" rpy="0 0 0"/>
            <geometry>
                <box size="0.4572163427382339 0.37454402304140644 0.46641514169863063" />
            </geometry>
        </collision>
    </link>
    <joint name="Link2_Link4" type="revolute">
       <parent link="Link2"/>
       <child  link="Link4"/>
       <origin rpy="0 0 0" xyz="0 0 0.7045739999923248" />
       <axis xyz="0 0 1"/>
       <limit effort="0.0" lower="-3.14159" upper="3.14159" velocity="0.0"/>
    </joint>
    <link name="Link4">
        <inertial>
            <origin xyz="0 0 0.22448875907759827" rpy="0 0 0"/>
            <mass value="1" />
            <inertia ixx="100" ixy="0" ixz="0" iyy="100" iyz="0" izz="100" />
        </inertial>
        <visual>
            <origin xyz="0 0 0.22448875907759827" rpy="0 0 0"/>
            <geometry>
                <box size="0.7238450419506115 0.4088640383364215 0.44897751815519654" />
            </geometry>
            <material name="Blue">
                <color rgba="0 0 1.0 1.0"/>
            </material>
        </visual>
        <collision>
            <origin xyz="0 0 0.22448875907759827" rpy="0 0 0"/>
            <geometry>
                <box size="0.7238450419506115 0.4088640383364215 0.44897751815519654" />
            </geometry>
        </collision>
    </link>
    <joint name="Link0_Link5" type="revolute">
       <parent link="Link0"/>
       <child  link="Link5"/>
       <origin rpy="0 0 0" xyz="0 0.1267408951722715 0.4728547826267998" />
       <axis xyz="1 0 0"/>
       <limit effort="0.0" lower="-3.14159" upper="3.14159" velocity="0.0"/>
    </joint>
    <link name="Link5">
        <inertial>
            <origin xyz="0 0.3391549303970375 0" rpy="0 0 0"/>
            <mass value="1" />
            <inertia ixx="100" ixy="0" ixz="0" iyy="100" iyz="0" izz="100" />
        </inertial>
        <visual>
            <origin xyz="0 0.3391549303970375 0" rpy="0 0 0"/>
            <geometry>
                <box size="0.3767518330708659 0.678309860794075 0.8291632471086345" />
            </geometry>
            <material name="Blue">
                <color rgba="0 0 1.0 1.0"/>
            </material>
        </visual>
        <collision>
            <origin xyz="0 0.3391549303970375 0" rpy="0 0 0"/>
            <geometry>
                <box size="0.3767518330708659 0.678309860794075 0.8291632471086345" />
            </geometry>
        </collision>
    </link>
    <joint name="Link5_Link6" type="revolute">
       <parent link="Link5"/>
       <child  link="Link6"/>
       <origin rpy="0 0 0" xyz="0 0.678309860794075 0" />
       <axis xyz="1 0 0"/>
       <limit effort="0.0" lower="-3.14159" upper="3.14159" velocity="0.0"/>
    </joint>
    <link name="Link6">
        <inertial>
            <origin xyz="0 0.47441362094190653 0" rpy="0 0 0"/>
            <mass value="1" />
            <inertia ixx="100" ixy="0" ixz="0" iyy="100" iyz="0" izz="100" />
        </inertial>
        <visual>
            <origin xyz="0 0.47441362094190653 0" rpy="0 0 0"/>
            <geometry>
                <box size="0.9077273890986124 0.9488272418838131 0.7518515891337734" />
            </geometry>
            <material name="Blue">
                <color rgba="0 0 1.0 1.0"/>
            </material>
        </visual>
        <collision>
            <origin xyz="0 0.47441362094190653 0" rpy="0 0 0"/>
            <geometry>
                <box size="0.9077273890986124 0.9488272418838131 0.7518515891337734" />
            </geometry>
        </collision>
    </link>
</robot>