<robot name = "robot">
    <link name="Link0">
        <inertial>
            <origin xyz="0 0 0.3083712099615723" rpy="0 0 0"/>
            <mass value="1" />
            <inertia ixx="100" ixy="0" ixz="0" iyy="100" iyz="0" izz="100" />
        </inertial>
        <visual>
            <origin xyz="0 0 0.3083712099615723" rpy="0 0 0"/>
            <geometry>
                <box size="0.8619626580188189 0.8807647254636184 0.6167424199231446" />
            </geometry>
            <material name="Green">
                <color rgba="0 1.0 0 1.0"/>
            </material>
        </visual>
        <collision>
            <origin xyz="0 0 0.3083712099615723" rpy="0 0 0"/>
            <geometry>
                <box size="0.8619626580188189 0.8807647254636184 0.6167424199231446" />
            </geometry>
        </collision>
    </link>
    <joint name="Link0_Link1" type="revolute">
       <parent link="Link0"/>
       <child  link="Link1"/>
       <origin rpy="0 0 0" xyz="0 0 0.6167424199231446" />
       <axis xyz="1 0 0"/>
       <limit effort="0.0" lower="-3.14159" upper="3.14159" velocity="0.0"/>
    </joint>
    <link name="Link1">
        <inertial>
            <origin xyz="0 0 0.4761326992450575" rpy="0 0 0"/>
            <mass value="1" />
            <inertia ixx="100" ixy="0" ixz="0" iyy="100" iyz="0" izz="100" />
        </inertial>
        <visual>
            <origin xyz="0 0 0.4761326992450575" rpy="0 0 0"/>
            <geometry>
                <box size="0.7240723293094806 0.5932149526681407 0.952265398490115" />
            </geometry>
            <material name="Blue">
                <color rgba="0 0 1.0 1.0"/>
            </material>
        </visual>
        <collision>
            <origin xyz="0 0 0.4761326992450575" rpy="0 0 0"/>
            <geometry>
                <box size="0.7240723293094806 0.5932149526681407 0.952265398490115" />
            </geometry>
        </collision>
    </link>
    <joint name="Link0_Link2" type="revolute">
       <parent link="Link0"/>
       <child  link="Link2"/>
       <origin rpy="0 0 0" xyz="0 -0.4403823627318092 0.3083712099615723" />
       <axis xyz="1 0 0"/>
       <limit effort="0.0" lower="-3.14159" upper="3.14159" velocity="0.0"/>
    </joint>
    <link name="Link2">
        <inertial>
            <origin xyz="0 -0.34583195255352817 0" rpy="0 0 0"/>
            <mass value="1" />
            <inertia ixx="100" ixy="0" ixz="0" iyy="100" iyz="0" izz="100" />
        </inertial>
        <visual>
            <origin xyz="0 -0.34583195255352817 0" rpy="0 0 0"/>
            <geometry>
                <box size="0.24192112226870668 0.6916639051070563 0.8400137816716671" />
            </geometry>
            <material name="Green">
                <color rgba="0 1.0 0 1.0"/>
            </material>
        </visual>
        <collision>
            <origin xyz="0 -0.34583195255352817 0" rpy="0 0 0"/>
            <geometry>
                <box size="0.24192112226870668 0.6916639051070563 0.8400137816716671" />
            </geometry>
        </collision>
    </link>
    <joint name="Link2_Link3" type="revolute">
       <parent link="Link2"/>
       <child  link="Link3"/>
       <origin rpy="0 0 0" xyz="-0.12096056113435334 -0.34583195255352817 0" />
       <axis xyz="1 0 0"/>
       <limit effort="0.0" lower="-3.14159" upper="3.14159" velocity="0.0"/>
    </joint>
    <link name="Link3">
        <inertial>
            <origin xyz="-0.14109259213336078 0 0" rpy="0 0 0"/>
            <mass value="1" />
            <inertia ixx="100" ixy="0" ixz="0" iyy="100" iyz="0" izz="100" />
        </inertial>
        <visual>
            <origin xyz="-0.14109259213336078 0 0" rpy="0 0 0"/>
            <geometry>
                <box size="0.28218518426672157 0.5120920278934659 0.6388777578651813" />
            </geometry>
            <material name="Green">
                <color rgba="0 1.0 0 1.0"/>
            </material>
        </visual>
        <collision>
            <origin xyz="-0.14109259213336078 0 0" rpy="0 0 0"/>
            <geometry>
                <box size="0.28218518426672157 0.5120920278934659 0.6388777578651813" />
            </geometry>
        </collision>
    </link>
</robot>