<robot name = "robot">
    <link name="Link0">
        <inertial>
            <origin xyz="0 0 0.4976467244628475" rpy="0 0 0"/>
            <mass value="1" />
            <inertia ixx="100" ixy="0" ixz="0" iyy="100" iyz="0" izz="100" />
        </inertial>
        <visual>
            <origin xyz="0 0 0.4976467244628475" rpy="0 0 0"/>
            <geometry>
                <box size="0.6091460522987651 0.7743941276618833 0.995293448925695" />
            </geometry>
            <material name="g">
                <color rgba="0.9 0.9 0.2 0.95"/>
            </material>
        </visual>
        <collision>
            <origin xyz="0 0 0.4976467244628475" rpy="0 0 0"/>
            <geometry>
                <box size="0.6091460522987651 0.7743941276618833 0.995293448925695" />
            </geometry>
        </collision>
    </link>
    <joint name="Link0_Link1" type="revolute">
       <parent link="Link0"/>
       <child  link="Link1"/>
       <origin rpy="0 0 0" xyz="-0.30457302614938253 0 0.4976467244628475" />
       <axis xyz="0 0 1"/>
       <limit effort="0.0" lower="-3.14159" upper="3.14159" velocity="0.0"/>
    </joint>
    <link name="Link1">
        <inertial>
            <origin xyz="-0.4734011388208049 0 0" rpy="0 0 0"/>
            <mass value="1" />
            <inertia ixx="100" ixy="0" ixz="0" iyy="100" iyz="0" izz="100" />
        </inertial>
        <visual>
            <origin xyz="-0.4734011388208049 0 0" rpy="0 0 0"/>
            <geometry>
                <box size="0.9468022776416098 0.9938925218408365 0.46669434164408596" />
            </geometry>
            <material name="a">
                <color rgba="0.1 0.2 0.9 0.95"/>
            </material>
        </visual>
        <collision>
            <origin xyz="-0.4734011388208049 0 0" rpy="0 0 0"/>
            <geometry>
                <box size="0.9468022776416098 0.9938925218408365 0.46669434164408596" />
            </geometry>
        </collision>
    </link>
    <joint name="Link0_Link2" type="revolute">
       <parent link="Link0"/>
       <child  link="Link2"/>
       <origin rpy="0 0 0" xyz="0 0 0.995293448925695" />
       <axis xyz="0 0 1"/>
       <limit effort="0.0" lower="-3.14159" upper="3.14159" velocity="0.0"/>
    </joint>
    <link name="Link2">
        <inertial>
            <origin xyz="0 0 0.4691615887627777" rpy="0 0 0"/>
            <mass value="1" />
            <inertia ixx="100" ixy="0" ixz="0" iyy="100" iyz="0" izz="100" />
        </inertial>
        <visual>
            <origin xyz="0 0 0.4691615887627777" rpy="0 0 0"/>
            <geometry>
                <box size="0.5698518365341583 0.3333770617482351 0.9383231775255554" />
            </geometry>
            <material name="b">
                <color rgba="0.4 0.9 0.1 0.95"/>
            </material>
        </visual>
        <collision>
            <origin xyz="0 0 0.4691615887627777" rpy="0 0 0"/>
            <geometry>
                <box size="0.5698518365341583 0.3333770617482351 0.9383231775255554" />
            </geometry>
        </collision>
    </link>
    <joint name="Link2_Link3" type="revolute">
       <parent link="Link2"/>
       <child  link="Link3"/>
       <origin rpy="0 0 0" xyz="-0.28492591826707914 0 0.4691615887627777" />
       <axis xyz="1 0 0"/>
       <limit effort="0.0" lower="-3.14159" upper="3.14159" velocity="0.0"/>
    </joint>
    <link name="Link3">
        <inertial>
            <origin xyz="-0.11783930459253461 0 0" rpy="0 0 0"/>
            <mass value="1" />
            <inertia ixx="100" ixy="0" ixz="0" iyy="100" iyz="0" izz="100" />
        </inertial>
        <visual>
            <origin xyz="-0.11783930459253461 0 0" rpy="0 0 0"/>
            <geometry>
                <box size="0.23567860918506922 0.8497939962218597 0.4841227760072333" />
            </geometry>
            <material name="c">
                <color rgba="0.5 0.9 0.4 0.95"/>
            </material>
        </visual>
        <collision>
            <origin xyz="-0.11783930459253461 0 0" rpy="0 0 0"/>
            <geometry>
                <box size="0.23567860918506922 0.8497939962218597 0.4841227760072333" />
            </geometry>
        </collision>
    </link>
    <joint name="Link3_Link4" type="revolute">
       <parent link="Link3"/>
       <child  link="Link4"/>
       <origin rpy="0 0 0" xyz="-0.11783930459253461 -0.42489699811092985 0" />
       <axis xyz="0 1 0"/>
       <limit effort="0.0" lower="-3.14159" upper="3.14159" velocity="0.0"/>
    </joint>
    <link name="Link4">
        <inertial>
            <origin xyz="0 -0.2118882808181466 0" rpy="0 0 0"/>
            <mass value="1" />
            <inertia ixx="100" ixy="0" ixz="0" iyy="100" iyz="0" izz="100" />
        </inertial>
        <visual>
            <origin xyz="0 -0.2118882808181466 0" rpy="0 0 0"/>
            <geometry>
                <box size="0.9925949693853686 0.4237765616362932 0.516562723465336" />
            </geometry>
            <material name="d">
                <color rgba="0.3 0.3 0.3 0.95"/>
            </material>
        </visual>
        <collision>
            <origin xyz="0 -0.2118882808181466 0" rpy="0 0 0"/>
            <geometry>
                <box size="0.9925949693853686 0.4237765616362932 0.516562723465336" />
            </geometry>
        </collision>
    </link>
    <joint name="Link0_Link5" type="revolute">
       <parent link="Link0"/>
       <child  link="Link5"/>
       <origin rpy="0 0 0" xyz="0 -0.38719706383094166 0.4976467244628475" />
       <axis xyz="1 0 0"/>
       <limit effort="0.0" lower="-3.14159" upper="3.14159" velocity="0.0"/>
    </joint>
    <link name="Link5">
        <inertial>
            <origin xyz="0 -0.31400022039939707 0" rpy="0 0 0"/>
            <mass value="1" />
            <inertia ixx="100" ixy="0" ixz="0" iyy="100" iyz="0" izz="100" />
        </inertial>
        <visual>
            <origin xyz="0 -0.31400022039939707 0" rpy="0 0 0"/>
            <geometry>
                <box size="0.6055486489209017 0.6280004407987941 0.533962739847534" />
            </geometry>
            <material name="e">
                <color rgba="0.5 0.8 0.3 0.95"/>
            </material>
        </visual>
        <collision>
            <origin xyz="0 -0.31400022039939707 0" rpy="0 0 0"/>
            <geometry>
                <box size="0.6055486489209017 0.6280004407987941 0.533962739847534" />
            </geometry>
        </collision>
    </link>
    <joint name="Link4_Link6" type="revolute">
       <parent link="Link4"/>
       <child  link="Link6"/>
       <origin rpy="0 0 0" xyz="-0.4962974846926843 -0.2118882808181466 0" />
       <axis xyz="0 0 1"/>
       <limit effort="0.0" lower="-3.14159" upper="3.14159" velocity="0.0"/>
    </joint>
    <link name="Link6">
        <inertial>
            <origin xyz="-0.17638741237033861 0 0" rpy="0 0 0"/>
            <mass value="1" />
            <inertia ixx="100" ixy="0" ixz="0" iyy="100" iyz="0" izz="100" />
        </inertial>
        <visual>
            <origin xyz="-0.17638741237033861 0 0" rpy="0 0 0"/>
            <geometry>
                <box size="0.35277482474067723 0.3727742158021438 0.36291526060153906" />
            </geometry>
            <material name="f">
                <color rgba="0.1 0.1 0.5 0.95"/>
            </material>
        </visual>
        <collision>
            <origin xyz="-0.17638741237033861 0 0" rpy="0 0 0"/>
            <geometry>
                <box size="0.35277482474067723 0.3727742158021438 0.36291526060153906" />
            </geometry>
        </collision>
    </link>
</robot>