<robot name = "robot">
    <link name="Link0">
        <inertial>
            <origin xyz="0 0 0.4329834080671191" rpy="0 0 0"/>
            <mass value="1" />
            <inertia ixx="100" ixy="0" ixz="0" iyy="100" iyz="0" izz="100" />
        </inertial>
        <visual>
            <origin xyz="0 0 0.4329834080671191" rpy="0 0 0"/>
            <geometry>
                <box size="0.4437139529784469 0.9333059980091003 0.8659668161342382" />
            </geometry>
            <material name="Blue">
                <color rgba="0 0 1.0 1.0"/>
            </material>
        </visual>
        <collision>
            <origin xyz="0 0 0.4329834080671191" rpy="0 0 0"/>
            <geometry>
                <box size="0.4437139529784469 0.9333059980091003 0.8659668161342382" />
            </geometry>
        </collision>
    </link>
    <joint name="Link0_Link1" type="revolute">
       <parent link="Link0"/>
       <child  link="Link1"/>
       <origin rpy="0 0 0" xyz="0 0.46665299900455015 0.4329834080671191" />
       <axis xyz="0 0 1"/>
       <limit effort="0.0" lower="-3.14159" upper="3.14159" velocity="0.0"/>
    </joint>
    <link name="Link1">
        <inertial>
            <origin xyz="0 0.3875974773441886 0" rpy="0 0 0"/>
            <mass value="1" />
            <inertia ixx="100" ixy="0" ixz="0" iyy="100" iyz="0" izz="100" />
        </inertial>
        <visual>
            <origin xyz="0 0.3875974773441886 0" rpy="0 0 0"/>
            <geometry>
                <box size="0.6790643121783947 0.7751949546883772 0.7018519792138977" />
            </geometry>
            <material name="Green">
                <color rgba="0 1.0 0 1.0"/>
            </material>
        </visual>
        <collision>
            <origin xyz="0 0.3875974773441886 0" rpy="0 0 0"/>
            <geometry>
                <box size="0.6790643121783947 0.7751949546883772 0.7018519792138977" />
            </geometry>
        </collision>
    </link>
    <joint name="Link1_Link2" type="revolute">
       <parent link="Link1"/>
       <child  link="Link2"/>
       <origin rpy="0 0 0" xyz="0 0.0 0" />
       <axis xyz="0 1 0"/>
       <limit effort="0.0" lower="-3.14159" upper="3.14159" velocity="0.0"/>
    </joint>
    <link name="Link2">
        <inertial>
            <origin xyz="0 -0.20228995939829392 0" rpy="0 0 0"/>
            <mass value="1" />
            <inertia ixx="100" ixy="0" ixz="0" iyy="100" iyz="0" izz="100" />
        </inertial>
        <visual>
            <origin xyz="0 -0.20228995939829392 0" rpy="0 0 0"/>
            <geometry>
                <box size="0.7327450506583482 0.40457991879658783 0.8099392241493817" />
            </geometry>
            <material name="Green">
                <color rgba="0 1.0 0 1.0"/>
            </material>
        </visual>
        <collision>
            <origin xyz="0 -0.20228995939829392 0" rpy="0 0 0"/>
            <geometry>
                <box size="0.7327450506583482 0.40457991879658783 0.8099392241493817" />
            </geometry>
        </collision>
    </link>
    <joint name="Link0_Link3" type="revolute">
       <parent link="Link0"/>
       <child  link="Link3"/>
       <origin rpy="0 0 0" xyz="0 -0.46665299900455015 0.4329834080671191" />
       <axis xyz="0 1 0"/>
       <limit effort="0.0" lower="-3.14159" upper="3.14159" velocity="0.0"/>
    </joint>
    <link name="Link3">
        <inertial>
            <origin xyz="0 -0.16141798844761582 0" rpy="0 0 0"/>
            <mass value="1" />
            <inertia ixx="100" ixy="0" ixz="0" iyy="100" iyz="0" izz="100" />
        </inertial>
        <visual>
            <origin xyz="0 -0.16141798844761582 0" rpy="0 0 0"/>
            <geometry>
                <box size="0.3556130484414016 0.32283597689523164 0.8573032420853932" />
            </geometry>
            <material name="Blue">
                <color rgba="0 0 1.0 1.0"/>
            </material>
        </visual>
        <collision>
            <origin xyz="0 -0.16141798844761582 0" rpy="0 0 0"/>
            <geometry>
                <box size="0.3556130484414016 0.32283597689523164 0.8573032420853932" />
            </geometry>
        </collision>
    </link>
    <joint name="Link0_Link4" type="revolute">
       <parent link="Link0"/>
       <child  link="Link4"/>
       <origin rpy="0 0 0" xyz="-0.22185697648922345 0 0.4329834080671191" />
       <axis xyz="0 1 0"/>
       <limit effort="0.0" lower="-3.14159" upper="3.14159" velocity="0.0"/>
    </joint>
    <link name="Link4">
        <inertial>
            <origin xyz="-0.109524483590539 0 0" rpy="0 0 0"/>
            <mass value="1" />
            <inertia ixx="100" ixy="0" ixz="0" iyy="100" iyz="0" izz="100" />
        </inertial>
        <visual>
            <origin xyz="-0.109524483590539 0 0" rpy="0 0 0"/>
            <geometry>
                <box size="0.219048967181078 0.24701524938296757 0.4583157264840414" />
            </geometry>
            <material name="Green">
                <color rgba="0 1.0 0 1.0"/>
            </material>
        </visual>
        <collision>
            <origin xyz="-0.109524483590539 0 0" rpy="0 0 0"/>
            <geometry>
                <box size="0.219048967181078 0.24701524938296757 0.4583157264840414" />
            </geometry>
        </collision>
    </link>
    <joint name="Link3_Link5" type="revolute">
       <parent link="Link3"/>
       <child  link="Link5"/>
       <origin rpy="0 0 0" xyz="0 -0.32283597689523164 0" />
       <axis xyz="0 1 0"/>
       <limit effort="0.0" lower="-3.14159" upper="3.14159" velocity="0.0"/>
    </joint>
    <link name="Link5">
        <inertial>
            <origin xyz="0 -0.10255669870533146 0" rpy="0 0 0"/>
            <mass value="1" />
            <inertia ixx="100" ixy="0" ixz="0" iyy="100" iyz="0" izz="100" />
        </inertial>
        <visual>
            <origin xyz="0 -0.10255669870533146 0" rpy="0 0 0"/>
            <geometry>
                <box size="0.7068548759991853 0.20511339741066292 0.4632995861412299" />
            </geometry>
            <material name="Green">
                <color rgba="0 1.0 0 1.0"/>
            </material>
        </visual>
        <collision>
            <origin xyz="0 -0.10255669870533146 0" rpy="0 0 0"/>
            <geometry>
                <box size="0.7068548759991853 0.20511339741066292 0.4632995861412299" />
            </geometry>
        </collision>
    </link>
</robot>