<robot name = "robot">
    <link name="Link0">
        <inertial>
            <origin xyz="0 0 0.2787232226626371" rpy="0 0 0"/>
            <mass value="1" />
            <inertia ixx="100" ixy="0" ixz="0" iyy="100" iyz="0" izz="100" />
        </inertial>
        <visual>
            <origin xyz="0 0 0.2787232226626371" rpy="0 0 0"/>
            <geometry>
                <box size="0.8327148101492399 0.25569459198704436 0.5574464453252742" />
            </geometry>
            <material name="Green">
                <color rgba="0 1.0 0 1.0"/>
            </material>
        </visual>
        <collision>
            <origin xyz="0 0 0.2787232226626371" rpy="0 0 0"/>
            <geometry>
                <box size="0.8327148101492399 0.25569459198704436 0.5574464453252742" />
            </geometry>
        </collision>
    </link>
    <joint name="Link0_Link1" type="revolute">
       <parent link="Link0"/>
       <child  link="Link1"/>
       <origin rpy="0 0 0" xyz="0 0 0.5574464453252742" />
       <axis xyz="0 1 0"/>
       <limit effort="0.0" lower="-3.14159" upper="3.14159" velocity="0.0"/>
    </joint>
    <link name="Link1">
        <inertial>
            <origin xyz="0 0 0.3197346680687821" rpy="0 0 0"/>
            <mass value="1" />
            <inertia ixx="100" ixy="0" ixz="0" iyy="100" iyz="0" izz="100" />
        </inertial>
        <visual>
            <origin xyz="0 0 0.3197346680687821" rpy="0 0 0"/>
            <geometry>
                <box size="0.22360662325441735 0.9826698895665642 0.6394693361375642" />
            </geometry>
            <material name="Blue">
                <color rgba="0 0 1.0 1.0"/>
            </material>
        </visual>
        <collision>
            <origin xyz="0 0 0.3197346680687821" rpy="0 0 0"/>
            <geometry>
                <box size="0.22360662325441735 0.9826698895665642 0.6394693361375642" />
            </geometry>
        </collision>
    </link>
    <joint name="Link1_Link2" type="revolute">
       <parent link="Link1"/>
       <child  link="Link2"/>
       <origin rpy="0 0 0" xyz="0 0.4913349447832821 0.3197346680687821" />
       <axis xyz="0 0 1"/>
       <limit effort="0.0" lower="-3.14159" upper="3.14159" velocity="0.0"/>
    </joint>
    <link name="Link2">
        <inertial>
            <origin xyz="0 0.4989722761778105 0" rpy="0 0 0"/>
            <mass value="1" />
            <inertia ixx="100" ixy="0" ixz="0" iyy="100" iyz="0" izz="100" />
        </inertial>
        <visual>
            <origin xyz="0 0.4989722761778105 0" rpy="0 0 0"/>
            <geometry>
                <box size="0.7324933614011544 0.997944552355621 0.2225377053767253" />
            </geometry>
            <material name="Green">
                <color rgba="0 1.0 0 1.0"/>
            </material>
        </visual>
        <collision>
            <origin xyz="0 0.4989722761778105 0" rpy="0 0 0"/>
            <geometry>
                <box size="0.7324933614011544 0.997944552355621 0.2225377053767253" />
            </geometry>
        </collision>
    </link>
    <joint name="Link1_Link3" type="revolute">
       <parent link="Link1"/>
       <child  link="Link3"/>
       <origin rpy="0 0 0" xyz="0 0 0.6394693361375642" />
       <axis xyz="0 0 1"/>
       <limit effort="0.0" lower="-3.14159" upper="3.14159" velocity="0.0"/>
    </joint>
    <link name="Link3">
        <inertial>
            <origin xyz="0 0 0.21987703343064538" rpy="0 0 0"/>
            <mass value="1" />
            <inertia ixx="100" ixy="0" ixz="0" iyy="100" iyz="0" izz="100" />
        </inertial>
        <visual>
            <origin xyz="0 0 0.21987703343064538" rpy="0 0 0"/>
            <geometry>
                <box size="0.5265573049184509 0.63752336921159 0.43975406686129076" />
            </geometry>
            <material name="Green">
                <color rgba="0 1.0 0 1.0"/>
            </material>
        </visual>
        <collision>
            <origin xyz="0 0 0.21987703343064538" rpy="0 0 0"/>
            <geometry>
                <box size="0.5265573049184509 0.63752336921159 0.43975406686129076" />
            </geometry>
        </collision>
    </link>
</robot>