<robot name = "robot">
    <link name="Link0">
        <inertial>
            <origin xyz="0 0 0.1882105541508428" rpy="0 0 0"/>
            <mass value="1" />
            <inertia ixx="100" ixy="0" ixz="0" iyy="100" iyz="0" izz="100" />
        </inertial>
        <visual>
            <origin xyz="0 0 0.1882105541508428" rpy="0 0 0"/>
            <geometry>
                <box size="0.8655152634319614 0.4934752167574463 0.3764211083016856" />
            </geometry>
            <material name="Green">
                <color rgba="0 1.0 0 1.0"/>
            </material>
        </visual>
        <collision>
            <origin xyz="0 0 0.1882105541508428" rpy="0 0 0"/>
            <geometry>
                <box size="0.8655152634319614 0.4934752167574463 0.3764211083016856" />
            </geometry>
        </collision>
    </link>
    <joint name="Link0_Link1" type="revolute">
       <parent link="Link0"/>
       <child  link="Link1"/>
       <origin rpy="0 0 0" xyz="0.4327576317159807 0 0.1882105541508428" />
       <axis xyz="0 1 0"/>
       <limit effort="0.0" lower="-3.14159" upper="3.14159" velocity="0.0"/>
    </joint>
    <joint name="Link0_Link1" type="revolute">
       <parent link="Link0"/>
       <child  link="Link1"/>
       <origin rpy="0 0 0" xyz="-0.4327576317159807 0 0.1882105541508428" />
       <axis xyz="0 0 1"/>
       <limit effort="0.0" lower="-3.14159" upper="3.14159" velocity="0.0"/>
    </joint>
    <link name="Link1">
        <inertial>
            <origin xyz="-0.2510564710173052 0 0" rpy="0 0 0"/>
            <mass value="1" />
            <inertia ixx="100" ixy="0" ixz="0" iyy="100" iyz="0" izz="100" />
        </inertial>
        <visual>
            <origin xyz="-0.2510564710173052 0 0" rpy="0 0 0"/>
            <geometry>
                <box size="0.5021129420346104 0.20942972424406925 0.7399520471896353" />
            </geometry>
            <material name="Blue">
                <color rgba="0 0 1.0 1.0"/>
            </material>
        </visual>
        <collision>
            <origin xyz="-0.2510564710173052 0 0" rpy="0 0 0"/>
            <geometry>
                <box size="0.5021129420346104 0.20942972424406925 0.7399520471896353" />
            </geometry>
        </collision>
    </link>
    <joint name="Link1_Link2" type="revolute">
       <parent link="Link1"/>
       <child  link="Link2"/>
       <origin rpy="0 0 0" xyz="0 0 0.5581865777456605" />
       <axis xyz="0 1 0"/>
       <limit effort="0.0" lower="-3.14159" upper="3.14159" velocity="0.0"/>
    </joint>
    <link name="Link2">
        <inertial>
            <origin xyz="0 0 0.180052472492052" rpy="0 0 0"/>
            <mass value="1" />
            <inertia ixx="100" ixy="0" ixz="0" iyy="100" iyz="0" izz="100" />
        </inertial>
        <visual>
            <origin xyz="0 0 0.180052472492052" rpy="0 0 0"/>
            <geometry>
                <box size="0.7964525928564536 0.6243921183072609 0.360104944984104" />
            </geometry>
            <material name="Green">
                <color rgba="0 1.0 0 1.0"/>
            </material>
        </visual>
        <collision>
            <origin xyz="0 0 0.180052472492052" rpy="0 0 0"/>
            <geometry>
                <box size="0.7964525928564536 0.6243921183072609 0.360104944984104" />
            </geometry>
        </collision>
    </link>
    <joint name="Link2_Link3" type="revolute">
       <parent link="Link2"/>
       <child  link="Link3"/>
       <origin rpy="0 0 0" xyz="0 0 0.008158081658790811" />
       <axis xyz="0 1 0"/>
       <limit effort="0.0" lower="-3.14159" upper="3.14159" velocity="0.0"/>
    </joint>
    <link name="Link3">
        <inertial>
            <origin xyz="0 0 -0.2970812626227579" rpy="0 0 0"/>
            <mass value="1" />
            <inertia ixx="100" ixy="0" ixz="0" iyy="100" iyz="0" izz="100" />
        </inertial>
        <visual>
            <origin xyz="0 0 -0.2970812626227579" rpy="0 0 0"/>
            <geometry>
                <box size="0.7185749712449221 0.6338957164835428 0.5941625252455158" />
            </geometry>
            <material name="Green">
                <color rgba="0 1.0 0 1.0"/>
            </material>
        </visual>
        <collision>
            <origin xyz="0 0 -0.2970812626227579" rpy="0 0 0"/>
            <geometry>
                <box size="0.7185749712449221 0.6338957164835428 0.5941625252455158" />
            </geometry>
        </collision>
    </link>
</robot>