<robot name = "robot">
    <link name="Link0">
        <inertial>
            <origin xyz="0 0 0.1490557831471211" rpy="0 0 0"/>
            <mass value="1" />
            <inertia ixx="100" ixy="0" ixz="0" iyy="100" iyz="0" izz="100" />
        </inertial>
        <visual>
            <origin xyz="0 0 0.1490557831471211" rpy="0 0 0"/>
            <geometry>
                <box size="0.9603803396452777 0.3518507441255656 0.2981115662942422" />
            </geometry>
            <material name="Green">
                <color rgba="0 1.0 0 1.0"/>
            </material>
        </visual>
        <collision>
            <origin xyz="0 0 0.1490557831471211" rpy="0 0 0"/>
            <geometry>
                <box size="0.9603803396452777 0.3518507441255656 0.2981115662942422" />
            </geometry>
        </collision>
    </link>
    <joint name="Link0_Link1" type="revolute">
       <parent link="Link0"/>
       <child  link="Link1"/>
       <origin rpy="0 0 0" xyz="0 0.1759253720627828 0.1490557831471211" />
       <axis xyz="0 0 1"/>
       <limit effort="0.0" lower="-3.14159" upper="3.14159" velocity="0.0"/>
    </joint>
    <link name="Link1">
        <inertial>
            <origin xyz="0 0.41115861658312547 0" rpy="0 0 0"/>
            <mass value="1" />
            <inertia ixx="100" ixy="0" ixz="0" iyy="100" iyz="0" izz="100" />
        </inertial>
        <visual>
            <origin xyz="0 0.41115861658312547 0" rpy="0 0 0"/>
            <geometry>
                <box size="0.4098887879237689 0.8223172331662509 0.4256584811081463" />
            </geometry>
            <material name="Green">
                <color rgba="0 1.0 0 1.0"/>
            </material>
        </visual>
        <collision>
            <origin xyz="0 0.41115861658312547 0" rpy="0 0 0"/>
            <geometry>
                <box size="0.4098887879237689 0.8223172331662509 0.4256584811081463" />
            </geometry>
        </collision>
    </link>
    <joint name="Link0_Link2" type="revolute">
       <parent link="Link0"/>
       <child  link="Link2"/>
       <origin rpy="0 0 0" xyz="0.48019016982263885 0 0.1490557831471211" />
       <axis xyz="0 1 0"/>
       <limit effort="0.0" lower="-3.14159" upper="3.14159" velocity="0.0"/>
    </joint>
    <link name="Link2">
        <inertial>
            <origin xyz="0.24431342177402204 0 0" rpy="0 0 0"/>
            <mass value="1" />
            <inertia ixx="100" ixy="0" ixz="0" iyy="100" iyz="0" izz="100" />
        </inertial>
        <visual>
            <origin xyz="0.24431342177402204 0 0" rpy="0 0 0"/>
            <geometry>
                <box size="0.4886268435480441 0.8451542130329361 0.21530198554331675" />
            </geometry>
            <material name="Green">
                <color rgba="0 1.0 0 1.0"/>
            </material>
        </visual>
        <collision>
            <origin xyz="0.24431342177402204 0 0" rpy="0 0 0"/>
            <geometry>
                <box size="0.4886268435480441 0.8451542130329361 0.21530198554331675" />
            </geometry>
        </collision>
    </link>
</robot>